Workbook

Sheet DAILY WEEKLY EXPENSES
E2: 30 DECEMBER - 5 JANUARY 2025 | M2: =E2 -> 30 DECEMBER - 5 JANUARY 2025 | V2: =M2 -> 30 DECEMBER - 5 JANUARY 2025
C3: SHOPS | D3: DAILY CASH INCOME | E3: WEEKLY INCOME | F3: ELECTRICITY | G3: FUEL/TOLL | H3: BAKELS | I3: CHIPKINS | J3: BAKERSBIN | K3: CAVALIERI | L3: WASI | M3: OBC | N3: MAKRO | O3: WAGES | P3: T/BANTU SWEETS | Q3: SHOPRITE | R3: COMPANY EXPENSES | S3: SPICE AND PACK | T3: KIA TRUCK PAYM REF | U3: GIFT TRUCK | V3: HYPER SWEETS | W3: OTHER | Y3: TOTALS
B4: 45656 | F4: 1500 | G4: =725.31+400 -> 1125.31 | L4: 6995.64 | N4: 679.8 | P4: =32+146 -> 178 | Q4: 439.88 | W4: 194.96 | X4: AE BARB | Y4: =SUM(F4:X8) -> 11121.58 | Z4: =B4 -> 45656
B5: MON | W5: 7.99 | X5: FAMILY STORE | Z5: MON
D8: =SUM(D4:D6) -> 0 | E8: =SUM(E4:E6) -> 0
B9: 45657 | G9: =79+79+744.67+1000 -> 1902.67 | J9: 3176 | L9: 5765.73 | P9: 90 | Q9: 286.9 | W9: 252 | X9: BACK 2 BASICS | Y9: =SUM(F9:W14) -> 19033.53 | Z9: =B9 -> 45657
B10: TUES | W10: 990.23 | X10: PNP | Z10: TUES
W11: 570 | X11: SOAP CENTRE
W12: 6000 | X12: HEIDEL EGGS
D14: =SUM(D9:D11) -> 0 | E14: =SUM(E9:E11) -> 0
B15: 45658 | G15: 1100 | Y15: =SUM(F15:X21) -> 1100 | Z15: =B15 -> 45658
B16: WED
D21: =SUM(D15:D20) -> 0 | E21: =SUM(E15:E20) -> 0
B22: 45659 | G22: 300 | L22: 6147.5 | W22: 131.98 | X22: PNP | Y22: =SUM(F22:W29) -> 14166.73 | Z22: =B22 -> 45659
B23: THU | W23: 7587.25 | X23: ACE
Z26: THU
D29: =SUM(D22:D28) -> 0 | E29: =SUM(E22:E28) -> 0
B30: 45660 | G30: 704.64 | Q30: 469.89 | Y30: =SUM(F30:W33) -> 1174.53 | Z30: =B30 -> 45660
B31: FRI
D33: =SUM(D30:D32) -> 0 | E33: =SUM(E30:E32) -> 0
B34: 45661 | F34: 1500 | G34: 750 | L34: 5716.55 | O34: =11710+6300 -> 18010 | Q34: 209.93 | Y34: =SUM(F34:W40) -> 26186.48 | Z34: =B34 -> 45661
B35: SAT | Z35: SAT
D40: =SUM(D34:D39) -> 0 | E40: =SUM(E34:E39) -> 0
B41: 45662 | W41: 178.98 | X41: PNP | Y41: =SUM(F41:W44) -> 408.15 | Z41: =B41 -> 45662
B42: SUN | W42: 189.17 | X42: AE BARB CS | Z42: SUN
W43: 40 | X43: REFUSE BAGS
D44: =SUM(D41:D43) -> 0 | E44: =SUM(E41:E43) -> 0
D47: =SUM(D44,D40,D33,D29,D21,D14,D8) -> 0 | E47: =SUM(E44,E40,E33,E29,E21,E14,E8) -> 0 | F47: =SUM(F4:F46) -> 3000 | G47: =SUM(G4:G46) -> 5882.62 | H47: =SUM(H4:H46) -> 0 | I47: =SUM(I4:I46) -> 0 | J47: =SUM(J4:J46) -> 3176 | K47: =SUM(K4:K46) -> 0 | L47: =SUM(L4:L46) -> 24625.42 | M47: =SUM(M4:M46) -> 0 | ... S47: =SUM(S4:S46) -> 0 | U47: =SUM(U8:U46) -> 0 | V47: =SUM(V4:V46) -> 0 | W47: =SUM(W4:W46) -> 16142.56 | Y47: =SUM(Y4:Y44) -> 73191
C48: SHOPS | D48: DAILY CASH INCOME | E48: WEEKLY INCOME | F48: ELECTRICITY | G48: FUEL/TOLL | H48: BAKELS | I48: CHIPKINS | J48: BAKERSBIN | K48: CAVALIERI | L48: WASI | M48: SARS | N48: MAKRO | O48: WAGES | P48: T/BANTU SWEETS | Q48: SHOPRITE | R48: COMPANY EXPENSES | S48: SPICE AND PACK | T48: KIA TRUCK PAYM REF | U48: GIFT TRUCK | V48: HYPER SWEETS | W48: OTHER | Y48: TOTALS
E49: =M49 -> 30 DECEMBER - 5 JANUARY 2025 | M49: =V49 -> 30 DECEMBER - 5 JANUARY 2025 | V49: =V2 -> 30 DECEMBER - 5 JANUARY 2025
E51: 6 - 12 JANUARY 2025 | M51: =E51 -> 6 - 12 JANUARY 2025 | V51: =M51 -> 6 - 12 JANUARY 2025
C52: SHOPS | D52: DAILY CASH INCOME | E52: WEEKLY INCOME | F52: ELECTRICITY | G52: FUEL/TOLL | H52: BAKELS | I52: CHIPKINS | J52: BAKERSBIN | K52: CAVALIERI | L52: WASI | M52: OBC | N52: MAKRO | O52: WAGES | P52: T/BANTU SWEETS | Q52: SHOPRITE | R52: COMPANY EXPENSES | S52: SPICE AND PACK | T52: KIA TRUCK PAYM REF | U52: GIFT TRUCK | V52: HYPER SWEETS | W52: OTHER | Y52: TOTALS
B53: 45663 | G53: 575.18 | K53: 575 | L53: 6021.55 | N53: 1733.8 | O53: 12725 | Q53: 299.9 | V53: 2472 | W53: 289 | X53: SHOP 2 SHOP | Y53: =SUM(F53:X57) -> 25261.43 | Z53: =B53 -> 45663
B54: MON | W54: 570 | X54: SOAP CENTRE | Z54: MON
D57: =SUM(D53:D55) -> 0 | E57: =SUM(E53:E55) -> 0
B58: 45664 | G58: =804.52+1500+79+79+400 -> 2862.52 | I58: 28014 | L58: 7522.57 | W58: =258.35 -> 258.35 | X58: ae barb cs | Y58: =SUM(F58:W63) -> 44910.4 | Z58: =B58 -> 45664
B59: TUES | W59: 51 | X59: AE CAROLINA | Z59: TUES
W60: 115 | X60: AE CAROLINA
W61: 86.96 | X61: PROBUILD
W62: 6000 | X62: HEIDEL EGGS
...

Sheet MONTHLY EXPENSES
C1: MONTHLY EXPENSES
A2: WEEKLY DATES | C2: ELEC | D2: FUEL/TOLL GATES | E2: HYPER SWEETS | F2: CHIPKINS | G2: BAKERSBIN | H2: CAVALIRI | I2: SHOPRITE | J2: WASI | K2: SPICE& PACK | L2: MAKRO | M2: WAGES | N2: OTHERS | O2: WEEKLY DATES | Q2: TOTALS
A3: 30 DEC - 5 JAN 2025 | C3: ='DAILY WEEKLY EXPENSES'!F47 -> 3000 | D3: ='DAILY WEEKLY EXPENSES'!G47 -> 5882.62 | E3: ='DAILY WEEKLY EXPENSES'!V47 -> 0 | F3: ='DAILY WEEKLY EXPENSES'!I47 -> 0 | G3: ='DAILY WEEKLY EXPENSES'!J47 -> 3176 | H3: ='DAILY WEEKLY EXPENSES'!K47 -> 0 | I3: ='DAILY WEEKLY EXPENSES'!Q47 -> 1406.6 | J3: ='DAILY WEEKLY EXPENSES'!L47 -> 24625.42 | K3: ='DAILY WEEKLY EXPENSES'!S47 -> 0 | L3: ='DAILY WEEKLY EXPENSES'!N47 -> 679.8 | M3: ='DAILY WEEKLY EXPENSES'!O47 -> 18010 | N3: ='DAILY WEEKLY EXPENSES'!W47 -> 16142.56 | O3: =A3 -> 30 DEC - 5 JAN 2025 | Q3: =SUM(C3:N3) -> 72923
A4: 6 - 12 JAN 2025 | C4: ='DAILY WEEKLY EXPENSES'!F96 -> 1500 | D4: ='DAILY WEEKLY EXPENSES'!G96 -> 6927.78 | E4: ='DAILY WEEKLY EXPENSES'!V96 -> 2472 | F4: ='DAILY WEEKLY EXPENSES'!I96 -> 28014 | G4: ='DAILY WEEKLY EXPENSES'!J96 -> 0 | H4: ='DAILY WEEKLY EXPENSES'!K96 -> 575 | I4: ='DAILY WEEKLY EXPENSES'!Q96 -> 1094.63 | J4: ='DAILY WEEKLY EXPENSES'!L96 -> 25266.15 | K4: ='DAILY WEEKLY EXPENSES'!S96 -> 0 | L4: ='DAILY WEEKLY EXPENSES'!N96 -> 1733.8 | M4: ='DAILY WEEKLY EXPENSES'!N96 -> 1733.8 | N4: ='DAILY WEEKLY EXPENSES'!W96 -> 22129.54 | O4: =A4 -> 6 - 12 JAN 2025 | Q4: =SUM(C4:N4) -> 91446.7
A5: 13 - 19 JAN 2025 | C5: ='DAILY WEEKLY EXPENSES'!F145 -> 1500 | D5: ='DAILY WEEKLY EXPENSES'!G145 -> 3184.12 | E5: ='DAILY WEEKLY EXPENSES'!V145 -> 672 | F5: ='DAILY WEEKLY EXPENSES'!I145 -> 0 | G5: ='DAILY WEEKLY EXPENSES'!J145 -> 0 | H5: ='DAILY WEEKLY EXPENSES'!K145 -> 0 | I5: ='DAILY WEEKLY EXPENSES'!Q145 -> 1224.65 | J5: ='DAILY WEEKLY EXPENSES'!L145 -> 25815.23 | K5: ='DAILY WEEKLY EXPENSES'!S145 -> 0 | L5: ='DAILY WEEKLY EXPENSES'!N145 -> 0 | M5: ='DAILY WEEKLY EXPENSES'!O145 -> 11325 | N5: ='DAILY WEEKLY EXPENSES'!W145 -> 12085.02 | O5: =A5 -> 13 - 19 JAN 2025 | Q5: =SUM(C5:N5) -> 55806.02
A6: 20 - 26 JAN 2025 | C6: ='DAILY WEEKLY EXPENSES'!F194 -> 0 | D6: ='DAILY WEEKLY EXPENSES'!G194 -> 6266.54 | E6: ='DAILY WEEKLY EXPENSES'!V194 -> 0 | F6: ='DAILY WEEKLY EXPENSES'!I194 -> 24276.5 | G6: ='DAILY WEEKLY EXPENSES'!J194 -> 0 | H6: ='DAILY WEEKLY EXPENSES'!K194 -> 0 | I6: ='DAILY WEEKLY EXPENSES'!Q194 -> 489.86 | J6: ='DAILY WEEKLY EXPENSES'!L194 -> 21064.3 | K6: ='DAILY WEEKLY EXPENSES'!S194 -> 9739.66 | L6: ='DAILY WEEKLY EXPENSES'!N194 -> 1153.3 | M6: ='DAILY WEEKLY EXPENSES'!O194 -> 22760 | N6: ='DAILY WEEKLY EXPENSES'!W194 -> 4298.34 | O6: =A6 -> 20 - 26 JAN 2025 | Q6: =SUM(C6:N6) -> 90048.5
A7: WEEKLY TOTALS | C7: =SUM(C3:C6) -> 6000 | D7: =SUM(D3:D6) -> 22261.06 | E7: =SUM(E3:E6) -> 3144 | F7: =SUM(F3:F6) -> 52290.5 | G7: =SUM(G3:G6) -> 3176 | H7: =SUM(H3:H6) -> 575 | I7: =SUM(I3:I6) -> 4215.74 | J7: =SUM(J3:J6) -> 96771.1 | ... N7: =SUM(N3:N6) -> 54655.46 | O7: =SUM(C7:N7) -> 310224.22 | P7: JANUARY | Q7: =SUM(Q3:Q6) -> 310224.22
A8: WEEKLY DATES | C8: ELEC | D8: FUEL/TOLL GATES | E8: HYPER SWEETS | F8: CHIPKINS | G8: BAKERSBIN | H8: CAVALIRI | I8: SHOPRITE | J8: WASI | K8: SPICE& PACK | L8: MAKRO | M8: WAGES | N8: OTHERS | O8: WEEKLY DATES | Q8: TOTALS
A9: 27 JAN - 2 FEB 2025 | C9: ='DAILY WEEKLY EXPENSES'!F243 -> 3000 | D9: ='DAILY WEEKLY EXPENSES'!G243 -> 4947.15 | E9: ='DAILY WEEKLY EXPENSES'!V243 -> 0 | F9: ='DAILY WEEKLY EXPENSES'!I243 -> 12186.33 | G9: ='DAILY WEEKLY EXPENSES'!J243 -> 0 | H9: ='DAILY WEEKLY EXPENSES'!K243 -> 0 | I9: ='DAILY WEEKLY EXPENSES'!Q243 -> 489.86 | J9: ='DAILY WEEKLY EXPENSES'!L243 -> 24346.18 | K9: ='DAILY WEEKLY EXPENSES'!S243 -> 7157.54 | L9: ='DAILY WEEKLY EXPENSES'!N243 -> 0 | M9: ='DAILY WEEKLY EXPENSES'!O243 -> 6900 | N9: ='DAILY WEEKLY EXPENSES'!W243 -> 7855.33 | O9: =A9 -> 27 JAN - 2 FEB 2025 | Q9: =SUM(C9:N9) -> 66882.39
A10: 3 - 9 FEB 2025 | C10: ='DAILY WEEKLY EXPENSES'!F292 -> 1500 | D10: ='DAILY WEEKLY EXPENSES'!G292 -> 4158 | E10: ='DAILY WEEKLY EXPENSES'!V292 -> 1200 | F10: ='DAILY WEEKLY EXPENSES'!I292 -> 24863 | G10: ='DAILY WEEKLY EXPENSES'!J292 -> 0 | H10: ='DAILY WEEKLY EXPENSES'!I292 -> 24863 | I10: ='DAILY WEEKLY EXPENSES'!Q292 -> 944.73 | J10: ='DAILY WEEKLY EXPENSES'!L292 -> 27106.96 | K10: ='DAILY WEEKLY EXPENSES'!S292 -> 7157.54 | L10: ='DAILY WEEKLY EXPENSES'!N292 -> 509.8 | M10: ='DAILY WEEKLY EXPENSES'!O292 -> 18755 | N10: ='DAILY WEEKLY EXPENSES'!W292 -> 10939.81 | O10: =A10 -> 3 - 9 FEB 2025 | Q10: =SUM(C10:N10) -> 121997.84
A11: 10 - 16 FEB 2025 | C11: ='DAILY WEEKLY EXPENSES'!F341 -> 3902.44 | D11: ='DAILY WEEKLY EXPENSES'!G341 -> 7127.17 | E11: ='DAILY WEEKLY EXPENSES'!V341 -> 0 | F11: ='DAILY WEEKLY EXPENSES'!I341 -> 1840 | G11: ='DAILY WEEKLY EXPENSES'!J341 -> 0 | H11: ='DAILY WEEKLY EXPENSES'!K341 -> 575 | I11: ='DAILY WEEKLY EXPENSES'!Q341 -> 1745.91 | J11: ='DAILY WEEKLY EXPENSES'!L341 -> 30395.05 | K11: ='DAILY WEEKLY EXPENSES'!S341 -> 0 | L11: ='DAILY WEEKLY EXPENSES'!N341 -> 1228.8 | M11: ='DAILY WEEKLY EXPENSES'!O341 -> 0 | N11: ='DAILY WEEKLY EXPENSES'!W341 -> 13918.69 | O11: =A11 -> 10 - 16 FEB 2025 | Q11: =SUM(C11:N11) -> 60733.06
A12: 17 - 23 FEB 2025 | C12: ='DAILY WEEKLY EXPENSES'!F390 -> 3000 | D12: ='DAILY WEEKLY EXPENSES'!G390 -> 5156.93 | E12: ='DAILY WEEKLY EXPENSES'!V390 -> 0 | F12: ='DAILY WEEKLY EXPENSES'!I390 -> 26460.13 | G12: ='DAILY WEEKLY EXPENSES'!J390 -> 0 | H12: ='DAILY WEEKLY EXPENSES'!K390 -> 0 | I12: ='DAILY WEEKLY EXPENSES'!Q390 -> 1230.81 | J12: ='DAILY WEEKLY EXPENSES'!L390 -> 22313.06 | K12: ='DAILY WEEKLY EXPENSES'!S390 -> 5731.95 | L12: ='DAILY WEEKLY EXPENSES'!N390 -> 0 | M12: ='DAILY WEEKLY EXPENSES'!O390 -> 6900 | N12: ='DAILY WEEKLY EXPENSES'!W390 -> 3194.54 | O12: =A12 -> 17 - 23 FEB 2025 | Q12: =SUM(C12:N12) -> 73987.42
A13: WEEKLY TOTALS | C13: =SUM(C9:C12) -> 11402.44 | D13: =SUM(D9:D12) -> 21389.25 | E13: =SUM(E9:E12) -> 1200 | F13: =SUM(F9:F12) -> 65349.46 | G13: =SUM(G9:G12) -> 0 | H13: =SUM(H9:H12) -> 25438 | I13: =SUM(I9:I12) -> 4411.31 | J13: =SUM(J9:J12) -> 104161.25 | ... N13: =SUM(N9:N12) -> 35908.37 | O13: =SUM(C13:N13) -> 323600.71 | P13: FEBRUARY | Q13: =SUM(Q9:Q12) -> 323600.71
A14: WEEKLY DATES | C14: ELEC | D14: FUEL/TOLL GATES | E14: HYPER SWEETS | F14: CHIPKINS | G14: BAKERSBIN | H14: CAVALIRI | I14: SHOPRITE | J14: WASI | K14: SPICE& PACK | L14: MAKRO | M14: WAGES | N14: OTHERS | O14: WEEKLY DATES | Q14: TOTALS
A15: 24 FEB - 2 MAR 2025 | C15: ='DAILY WEEKLY EXPENSES'!F439 -> 1500 | D15: ='DAILY WEEKLY EXPENSES'!G439 -> 4000.17 | E15: ='DAILY WEEKLY EXPENSES'!V439 -> 1200 | F15: ='DAILY WEEKLY EXPENSES'!I439 -> 10521.58 | G15: ='DAILY WEEKLY EXPENSES'!J439 -> 0 | H15: ='DAILY WEEKLY EXPENSES'!K439 -> 575 | I15: ='DAILY WEEKLY EXPENSES'!Q439 -> 1279.72 | J15: ='DAILY WEEKLY EXPENSES'!L439 -> 34524.15 | K15: ='DAILY WEEKLY EXPENSES'!S439 -> 7157.54 | L15: ='DAILY WEEKLY EXPENSES'!N439 -> 2588.9 | M15: ='DAILY WEEKLY EXPENSES'!O439 -> 14530 | N15: ='DAILY WEEKLY EXPENSES'!W439 -> 7074.16 | O15: =A15 -> 24 FEB - 2 MAR 2025 | Q15: =SUM(C15:N15) -> 84951.22
A16: 3 - 9 MAR 2025 | C16: ='DAILY WEEKLY EXPENSES'!F489 -> 0 | D16: ='DAILY WEEKLY EXPENSES'!G489 -> 5952.33 | E16: ='DAILY WEEKLY EXPENSES'!V489 -> 0 | F16: ='DAILY WEEKLY EXPENSES'!I489 -> 10039.5 | G16: ='DAILY WEEKLY EXPENSES'!J489 -> 0 | H16: ='DAILY WEEKLY EXPENSES'!K489 -> 0 | I16: ='DAILY WEEKLY EXPENSES'!Q489 -> 1123.72 | J16: ='DAILY WEEKLY EXPENSES'!L489 -> 33226.06 | K16: ='DAILY WEEKLY EXPENSES'!S489 -> 0 | L16: ='DAILY WEEKLY EXPENSES'!N489 -> 3258.8 | M16: ='DAILY WEEKLY EXPENSES'!O489 -> 18610 | N16: ='DAILY WEEKLY EXPENSES'!W489 -> 3822.89 | O16: =A16 -> 3 - 9 MAR 2025 | Q16: =SUM(C16:N16) -> 76033.3
A17: 10 - 16 MAR 2025 | C17: ='DAILY WEEKLY EXPENSES'!F539 -> 3000 | D17: ='DAILY WEEKLY EXPENSES'!G539 -> 3445.24 | E17: ='DAILY WEEKLY EXPENSES'!V539 -> 1200 | F17: ='DAILY WEEKLY EXPENSES'!I539 -> 19333.8 | G17: ='DAILY WEEKLY EXPENSES'!J539 -> 0 | H17: ='DAILY WEEKLY EXPENSES'!K539 -> 0 | I17: ='DAILY WEEKLY EXPENSES'!Q539 -> 1349.7 | J17: ='DAILY WEEKLY EXPENSES'!L539 -> 27534.52 | K17: ='DAILY WEEKLY EXPENSES'!S539 -> 4771.7 | L17: ='DAILY WEEKLY EXPENSES'!N539 -> 0 | M17: ='DAILY WEEKLY EXPENSES'!O539 -> 17855 | N17: ='DAILY WEEKLY EXPENSES'!W539 -> 1359.98 | O17: =A17 -> 10 - 16 MAR 2025 | Q17: =SUM(C17:N17) -> 79849.94
A18: 17-23 MAR 2025 | C18: ='DAILY WEEKLY EXPENSES'!F591 -> 0 | D18: ='DAILY WEEKLY EXPENSES'!G591 -> 5200.37 | E18: ='DAILY WEEKLY EXPENSES'!V591 -> 0 | F18: ='DAILY WEEKLY EXPENSES'!I591 -> 18571.13 | G18: ='DAILY WEEKLY EXPENSES'!J591 -> 0 | H18: ='DAILY WEEKLY EXPENSES'!K591 -> 4906.73 | I18: ='DAILY WEEKLY EXPENSES'!Q591 -> 1329.71 | J18: ='DAILY WEEKLY EXPENSES'!L591 -> 25320.34 | K18: ='DAILY WEEKLY EXPENSES'!S591 -> 7157.54 | L18: ='DAILY WEEKLY EXPENSES'!N591 -> 778 | M18: ='DAILY WEEKLY EXPENSES'!O591 -> 0 | N18: ='DAILY WEEKLY EXPENSES'!W591 -> 5353.95 | O18: =A18 -> 17-23 MAR 2025 | Q18: =SUM(C18:N18) -> 68617.77
A19: WEEKLY TOTALS | C19: =SUM(C15:C18) -> 4500 | D19: =SUM(D15:D18) -> 18598.11 | E19: =SUM(E15:E18) -> 2400 | F19: =SUM(F15:F18) -> 58466.01 | G19: =SUM(G15:G18) -> 0 | H19: =SUM(H15:H18) -> 5481.73 | I19: =SUM(I15:I18) -> 5082.85 | J19: =SUM(J15:J18) -> 120605.07 | ... N19: =SUM(N15:N18) -> 17610.98 | O19: =SUM(C19:N19) -> 309452.23 | P19: MARCH | Q19: =SUM(Q15:Q18) -> 309452.23
A20: WEEKLY DATES | C20: ELEC | D20: FUEL/TOLL GATES | E20: HYPER SWEETS | F20: CHIPKINS | G20: BAKERSBIN | H20: CAVALIRI | I20: SHOPRITE | J20: WASI | K20: SPICE& PACK | L20: MAKRO | M20: WAGES | N20: OTHERS | O20: WEEKLY DATES | Q20: TOTALS
A21: 24 - 30 MAR 2025 | C21: ='DAILY WEEKLY EXPENSES'!F641 -> 1500 | D21: ='DAILY WEEKLY EXPENSES'!G641 -> 4361.61 | E21: ='DAILY WEEKLY EXPENSES'!V641 -> 600 | F21: ='DAILY WEEKLY EXPENSES'!I641 -> 4358.5 | G21: ='DAILY WEEKLY EXPENSES'!J641 -> 0 | H21: ='DAILY WEEKLY EXPENSES'!K641 -> 575 | I21: ='DAILY WEEKLY EXPENSES'!Q641 -> 1664.63 | J21: ='DAILY WEEKLY EXPENSES'!L641 -> 34564.89 | K21: ='DAILY WEEKLY EXPENSES'!S641 -> 7157.54 | L21: ='DAILY WEEKLY EXPENSES'!N641 -> 1327.8 | M21: ='DAILY WEEKLY EXPENSES'!O641 -> 16235 | N21: ='DAILY WEEKLY EXPENSES'!W641 -> 1431.12 | O21: =A21 -> 24 - 30 MAR 2025 | Q21: =SUM(C21:N21) -> 73776.09
A22: 31 MAR - 6 APR 2025 | C22: ='DAILY WEEKLY EXPENSES'!F691 -> 1600 | D22: ='DAILY WEEKLY EXPENSES'!G691 -> 5378.04 | E22: ='DAILY WEEKLY EXPENSES'!V691 -> 0 | F22: ='DAILY WEEKLY EXPENSES'!I691 -> 21959.25 | G22: ='DAILY WEEKLY EXPENSES'!J691 -> 0 | H22: ='DAILY WEEKLY EXPENSES'!K691 -> 0 | I22: ='DAILY WEEKLY EXPENSES'!Q691 -> 1599.66 | J22: ='DAILY WEEKLY EXPENSES'!L691 -> 20183.88 | K22: ='DAILY WEEKLY EXPENSES'!S691 -> 7157.54 | L22: ='DAILY WEEKLY EXPENSES'!N691 -> 0 | M22: ='DAILY WEEKLY EXPENSES'!O691 -> 18670 | N22: ='DAILY WEEKLY EXPENSES'!W691 -> 5485.78 | O22: =A22 -> 31 MAR - 6 APR 2025 | Q22: =SUM(C22:N22) -> 82034.15
A23: 7 - 13 APR 2025 | C23: ='DAILY WEEKLY EXPENSES'!F741 -> 1500 | D23: ='DAILY WEEKLY EXPENSES'!G741 -> 3857.89 | E23: ='DAILY WEEKLY EXPENSES'!V741 -> 0 | F23: ='DAILY WEEKLY EXPENSES'!I741 -> 19859.13 | G23: ='DAILY WEEKLY EXPENSES'!H741 -> 0 | H23: ='DAILY WEEKLY EXPENSES'!K741 -> 548.32 | I23: ='DAILY WEEKLY EXPENSES'!Q741 -> 799.84 | J23: ='DAILY WEEKLY EXPENSES'!L741 -> 28241.97 | K23: ='DAILY WEEKLY EXPENSES'!S741 -> 7157.54 | L23: ='DAILY WEEKLY EXPENSES'!N741 -> 0 | M23: ='DAILY WEEKLY EXPENSES'!O741 -> 14820 | N23: ='DAILY WEEKLY EXPENSES'!W741 -> 2448.24 | O23: =A23 -> 7 - 13 APR 2025 | Q23: =SUM(C23:N23) -> 79232.93
A24: 14 - 20 APR 2025 | C24: ='DAILY WEEKLY EXPENSES'!F791 -> 1500 | D24: ='DAILY WEEKLY EXPENSES'!G791 -> 6557.04 | E24: ='DAILY WEEKLY EXPENSES'!V791 -> 0 | F24: ='DAILY WEEKLY EXPENSES'!I791 -> 33752.5 | G24: ='DAILY WEEKLY EXPENSES'!J791 -> 0 | H24: ='DAILY WEEKLY EXPENSES'!K791 -> 548.32 | I24: ='DAILY WEEKLY EXPENSES'!Q791 -> 2401.47 | J24: ='DAILY WEEKLY EXPENSES'!L791 -> 45594.09 | K24: ='DAILY WEEKLY EXPENSES'!S791 -> 7157.54 | L24: ='DAILY WEEKLY EXPENSES'!N791 -> 1005 | M24: ='DAILY WEEKLY EXPENSES'!O791 -> 0 | N24: ='DAILY WEEKLY EXPENSES'!W791 -> 4592.97 | O24: =A24 -> 14 - 20 APR 2025 | Q24: =SUM(C24:N24) -> 103108.93
A25: WEEKLY TOTALS | C25: =SUM(C21:C24) -> 6100 | D25: =SUM(D21:D24) -> 20154.58 | E25: =SUM(E21:E24) -> 600 | F25: =SUM(F21:F24) -> 79929.38 | G25: =SUM(G21:G24) -> 0 | H25: =SUM(H21:H24) -> 1671.64 | I25: =SUM(I21:I24) -> 6465.6 | J25: =SUM(J21:J24) -> 128584.83 | ... O25: =SUM(O21:O24) -> 0 | P25: APRIL | Q25: =SUM(Q21:Q24) -> 338152.1
A26: WEEKLY DATES | C26: ELEC | D26: FUEL/TOLL GATES | E26: HYPER SWEETS | F26: CHIPKINS | G26: BAKERSBIN | H26: CAVALIRI | I26: SHOPRITE | J26: WASI | K26: SPICE& PACK | L26: MAKRO | M26: WAGES | N26: OTHERS | O26: WEEKLY DATES | Q26: TOTALS
A27: 21 - 27 APR 2025 | C27: ='DAILY WEEKLY EXPENSES'!F841 -> 1500 | D27: ='DAILY WEEKLY EXPENSES'!G841 -> 5328.95 | E27: ='DAILY WEEKLY EXPENSES'!V841 -> 0 | F27: ='DAILY WEEKLY EXPENSES'!I841 -> 0 | G27: ='DAILY WEEKLY EXPENSES'!J841 -> 0 | H27: ='DAILY WEEKLY EXPENSES'!K841 -> 0 | I27: ='DAILY WEEKLY EXPENSES'!Q841 -> 1790.2 | J27: ='DAILY WEEKLY EXPENSES'!L841 -> 29274.16 | K27: ='DAILY WEEKLY EXPENSES'!S841 -> 7157.54 | L27: ='DAILY WEEKLY EXPENSES'!N841 -> 5733.9 | M27: ='DAILY WEEKLY EXPENSES'!O841 -> 43235 | N27: ='DAILY WEEKLY EXPENSES'!W841 -> 807.99 | O27: =A27 -> 21 - 27 APR 2025 | Q27: =SUM(C27:N27) -> 94827.74
A28: 28 APR - 4 MAY 2025 | C28: ='DAILY WEEKLY EXPENSES'!F891 -> 1500 | D28: ='DAILY WEEKLY EXPENSES'!G891 -> 5181.15 | E28: ='DAILY WEEKLY EXPENSES'!V891 -> 0 | F28: ='DAILY WEEKLY EXPENSES'!I891 -> 20531.88 | G28: ='DAILY WEEKLY EXPENSES'!J891 -> 0 | H28: ='DAILY WEEKLY EXPENSES'!K891 -> 0 | I28: ='DAILY WEEKLY EXPENSES'!Q891 -> 2302.39 | J28: ='DAILY WEEKLY EXPENSES'!L891 -> 38351.6 | K28: ='DAILY WEEKLY EXPENSES'!S891 -> 7157.54 | L28: ='DAILY WEEKLY EXPENSES'!N891 -> 0 | M28: ='DAILY WEEKLY EXPENSES'!O891 -> 19450 | N28: ='DAILY WEEKLY EXPENSES'!W891 -> 1384.96 | O28: =A28 -> 28 APR - 4 MAY 2025 | Q28: =SUM(C28:N28) -> 95859.52
O29: =A29 -> 0 | Q29: =SUM(C29:N29) -> 0
O30: =A30 -> 0 | Q30: =SUM(C30:N30) -> 0
A31: WEEKLY TOTALS | C31: =SUM(C27:C30) -> 3000 | D31: =SUM(D27:D30) -> 10510.1 | E31: =SUM(E27:E30) -> 0 | F31: =SUM(F27:F30) -> 20531.88 | G31: =SUM(G27:G30) -> 0 | H31: =SUM(H27:H30) -> 0 | I31: =SUM(I27:I30) -> 4092.59 | J31: =SUM(J27:J30) -> 67625.76 | ... O31: =SUM(O27:O30) -> 0 | P31: MAY | Q31: =SUM(Q27:Q30) -> 190687.26
A32: WEEKLY DATES | C32: ELEC | D32: FUEL/TOLL GATES | E32: HYPER SWEETS | F32: CHIPKINS | G32: BAKERSBIN | H32: CAVALIRI | I32: SHOPRITE | J32: WASI | K32: SPICE& PACK | L32: MAKRO | M32: WAGES | N32: OTHERS | O32: WEEKLY DATES | Q32: TOTALS
O33: =A33 -> 0 | Q33: =SUM(C33:N33) -> 0
O34: =A34 -> 0 | Q34: =SUM(C34:N34) -> 0
O35: =A35 -> 0 | Q35: =SUM(C35:N35) -> 0
O36: =A36 -> 0 | Q36: =SUM(C36:N36) -> 0
A37: WEEKLY TOTALS | C37: =SUM(C33:C36) -> 0 | D37: =SUM(D33:D36) -> 0 | E37: =SUM(E33:E36) -> 0 | F37: =SUM(F33:F36) -> 0 | G37: =SUM(G33:G36) -> 0 | H37: =SUM(H33:H36) -> 0 | I37: =SUM(I33:I36) -> 0 | J37: =SUM(J33:J36) -> 0 | ... O37: =SUM(O33:O36) -> 0 | P37: JUNE | Q37: =SUM(Q33:Q36) -> 0
A38: WEEKLY DATES | C38: ELEC | D38: FUEL/TOLL GATES | E38: HYPER SWEETS | F38: CHIPKINS | G38: BAKERSBIN | H38: CAVALIRI | I38: SHOPRITE | J38: WASI | K38: SPICE& PACK | L38: MAKRO | M38: WAGES | N38: OTHERS | O38: WEEKLY DATES | Q38: TOTALS
O39: =A39 -> 0 | Q39: =SUM(C39:N39) -> 0
O40: =A40 -> 0 | Q40: =SUM(C40:N40) -> 0
...

Sheet DAILY WEEKLY EXPENSES STOCK
B2: Week | C2: 30 DECEMBER - 5 JANUARY 2025 | L2: =C2 -> 30 DECEMBER - 5 JANUARY 2025 | AI2: =L2 -> 30 DECEMBER - 5 JANUARY 2025 | AW2: =AI2 -> 30 DECEMBER - 5 JANUARY 2025 | AX2: 22 - 28 MARCH 2021
G3: Flour | I3: Wsugar | K3: Bsugar | M3: Oil | O3: Eggs | Q3: Ricoffy | S3: Wspoon | U3: IcingS | W3: Bpowder | Y3: Bicarb | AA3: Cocoa | AC3: Milk | AE3: Carrots | AG3: Ccheese | AI3: Salt | AK3: Vanilla | AM3: Lemon Juice | AO3: Choc Slabs | AQ3: Van Slabs | AS3: Cinnamon | AU3: Red Cherries | AW3: Domes | AY3: Bases | BA3: Vinegar | BC3: Pecan Nuts | BE3: Cremora
B4: Date | C4: Total | F4: Supplier | G4: 12.5kg | I4: 10kg | K4: 10kg | M4: 5LITRES | O4: 180 | Q4: 750G | S4: 25kg | U4: 25kg | W4: 20kg | Y4: 25kg | AA4: 25kg | AC4: 6 x 1litres | AE4: 5kg | AG4: 5kg | AI4: 1kg | AK4: 3 LITRE | AM4: 2 L | AO4: 20 | AQ4: 20 | AS4: 5kg | AU4: 6 KG | AW4: 100 | AY4: 100 | BA4: 5litres | BC4: 10kg | BE4: 750G
C5: Amount | E5: OTHERS | F5: Price item | G5: 151 | I5: 167.99 | K5: 144.99 | M5: 169.99 | O5: 274.99 | Q5: 135 | S5: 910.5 | U5: 460.75 | W5: 1048.95 | Y5: 772.8 | AA5: 3450 | AC5: 99.99 | AE5: 29.99 | AG5: 548 | AI5: 4.99 | AK5: 132.25 | AM5: 47.99 | AO5: 560 | AQ5: 560 | AS5: 613.5 | AU5: 313.9 | AW5: 405.8 | AY5: 218.99 | BA5: 24.99 | BC5: 1425 | BE5: 54.99
B6: 45656 | C6: 1125.31 | E6: DIESEL
C7: 194.96 | E7: AE BARB
C8: 1500 | E8: ELECTRICITY
C9: 7.99 | E9: FAMILY STORE
C10: 439.88 | F10: SHOPRITE | AE10: 10 | AF10: 299.9 | AK10: 2 | AL10: 139.98
C11: 679.8 | F11: MAKRO | AK11: 4 | AL11: 679.8
C12: 6995.64 | F12: WASI | G12: 9 | H12: 1259.91 | I12: 2 | J12: 409.98 | K12: 4 | L12: 727.96 | M12: 12 | N12: 1739.88 | O12: 18 | P12: =1820+520 -> 2340 | W12: 6 | X12: 329.94 | AM12: 1 | AN12: 49.99 | BA12: 1 | BB12: 27.99 | BE12: 1 | BF12: 59.99
C13: =32+146 -> 178 | E13: TBANTU
B16: MON
C17: =SUM(C6:C16) -> 11121.58
B18: 45657 | C18: =79+79+744.67+1000 -> 1902.67 | E18: DIESEL/TOLL GATES
C19: 3176 | F19: BAKERSBIN | AW19: 2 | AX19: 1969 | AY19: 2 | AZ19: 1207
C20: 252 | E20: BACK 2 BASICS
C21: 5765.73 | F21: WASI | G21: 4 | H21: 559.96 | I21: 2 | J21: 409.98 | K21: 8 | L21: 1455.92 | M21: 8 | N21: 1159.92 | O21: 5 | P21: 1850 | W21: 4 | X21: 219.96 | BE21: 1 | BF21: 59.99
C22: 286.9 | F22: SHOPRITE | AE22: 9 | AF22: 269.91
C23: 990.23 | E23: PNP
C24: 570 | E24: SOAP CENTRE
C25: 90 | E25: TBANTU
B26: TUE | C26: 6000 | F26: EGGS | O26: 10 | P26: 6000
C27: =SUM(C18:C26) -> 19033.53
B28: 45658 | C28: 1100 | E28: DIESEL
B29: WED
C30: =SUM(C28:C29) -> 1100
B31: 45659 | C31: 300 | E31: DIESEL
C32: 131.98 | F32: PNP | W32: 2 | X32: 131.98
C33: 6147.5 | F33: WASI | G33: 12 | H33: 1643.88 | I33: 6 | J33: 617.94 | K33: 6 | L33: 1091.94 | M33: 12 | N33: 1739.88 | W33: 6 | X33: 539.94 | AC33: 4 | AD33: 395.96 | AI33: 2 | AJ33: 11.98 | BA33: 1 | BB33: 55.98
B34: THU | C34: 7587.25 | F34: ACE | AW34: 15 | AX34: 4578.83 | AY34: 15 | AZ34: 3008.42
C35: =SUM(C31:C34) -> 14166.73
B36: 45660 | C36: 704.64 | E36: DIESEL
C37: 469.89 | F37: SHOPRITE | AC37: 2 | AD37: 199.98 | AE37: 6 | AF37: =AE37*29.99 -> 179.94 | BA37: 3 | BB37: 89.97
B41: FRI
C42: =SUM(C36:C41) -> 1174.53
B43: 45661 | C43: 18010 | E43: WAGES
C44: 750 | E44: DIESEL
C45: 1500 | E45: ELECTRICITY
C46: 209.93 | F46: SHOPRITE | AE46: 5 | AF46: 149.95
...

Sheet MONTHLY STOCK
A2: MONTHLY STOCK
A3: 45658 | C3: STOCK | F3: Flour | H3: Wsugar | J3: Bsugar | L3: Oil | N3: Eggs | P3: Ricoffy | R3: Wspoon | T3: IcingS | V3: Bpowder | X3: Bicarb | Z3: Cocoa | AB3: Milk | AD3: Carrots | AF3: Ccheese | AH3: Salt | AJ3: Vanilla | AL3: Lemon Juice | AN3: Choc Slabs | AP3: Van Slabs | AR3: Cinnamon | AT3: Red Cherries | AV3: Domes | AX3: Bases | AZ3: Vinegar | BB3: Pecan Nuts | BD3: Cremora
F4: 12.5kg | H4: 10kg | J4: 10kg | L4: 5LITRES | N4: 180 | P4: 750G | R4: 25kg | T4: 25kg | V4: 20kg | X4: 25kg | Z4: 25kg | AB4: 6 x 1litres | AD4: 5kg | AF4: 5kg | AH4: 1kg | AJ4: 3 LITRE | AL4: 2 L | AN4: 20 | AP4: 20 | AR4: 5kg | AT4: 6 KG | AV4: 100 | AX4: 100 | AZ4: 5litres | BB4: 10kg | BD4: 750G
C5: WEEKLY DATES | F5: QUANTITY | G5: TOTALS | H5: QUANTITY | I5: TOTALS | J5: QUANTITY | K5: TOTALS | L5: QUANTITY | M5: TOTALS | N5: QUANTITY | O5: TOTALS | P5: QUANTITY | Q5: TOTALS | R5: QUANTITY | S5: TOTALS | T5: QUANTITY | U5: TOTALS | V5: QUANTITY | W5: TOTALS | X5: QUANTITY | Y5: TOTALS | Z5: QUANTITY | AA5: TOTALS | AB5: QUANTITY | AC5: TOTALS | AD5: QUANTITY | AE5: TOTALS | AF5: QUANTITY | AG5: TOTALS | AH5: QUANTITY | AI5: TOTALS | AJ5: QUANTITY | AK5: TOTALS | AL5: QUANTITY | AM5: TOTALS | AN5: QUANTITY | AO5: TOTALS | AP5: QUANTITY | AQ5: TOTALS | AR5: QUANTITY | AS5: TOTALS | AT5: QUANTITY | AU5: TOTALS | AV5: QUANTITY | AW5: TOTALS | AX5: QUANTITY | AY5: TOTALS | AZ5: QUANTITY | BA5: TOTALS | BB5: QUANTITY | BC5: TOTALS | BD5: QUANTITY | BE5: TOTALS
C6: 30 DEC - 5 JAN 2025 | F6: ='DAILY WEEKLY EXPENSES STOCK'!G60 -> 24 | G6: ='DAILY WEEKLY EXPENSES STOCK'!H60 -> 3299.76 | H6: ='DAILY WEEKLY EXPENSES STOCK'!I60 -> 12 | I6: ='DAILY WEEKLY EXPENSES STOCK'!J60 -> 1439.88 | J6: ='DAILY WEEKLY EXPENSES STOCK'!K60 -> 20 | K6: ='DAILY WEEKLY EXPENSES STOCK'!L60 -> 3639.8 | L6: ='DAILY WEEKLY EXPENSES STOCK'!M60 -> 32 | M6: ='DAILY WEEKLY EXPENSES STOCK'!N60 -> 4639.68 | ... BE6: ='DAILY WEEKLY EXPENSES STOCK'!BF60 -> 117.98
C7: 6 - 12 JAN 2025 | F7: ='DAILY WEEKLY EXPENSES STOCK'!G130 -> 28 | G7: ='DAILY WEEKLY EXPENSES STOCK'!H130 -> 3865.72 | H7: ='DAILY WEEKLY EXPENSES STOCK'!I130 -> 16 | I7: ='DAILY WEEKLY EXPENSES STOCK'!J130 -> 1647.84 | J7: ='DAILY WEEKLY EXPENSES STOCK'!K130 -> 22 | K7: ='DAILY WEEKLY EXPENSES STOCK'!L130 -> 4003.78 | L7: ='DAILY WEEKLY EXPENSES STOCK'!M130 -> 30 | M7: ='DAILY WEEKLY EXPENSES STOCK'!N130 -> 4389.7 | ... BE7: ='DAILY WEEKLY EXPENSES STOCK'!BF130 -> 191.97
C8: 13 - 19 JAN 2025 | F8: 29 | G8: 3972.71 | H8: 11 | I8: 1540.89 | J8: 22 | K8: 4003.78 | L8: 31 | M8: 4645.75 | N8: 18 | O8: 9725 | P8: 1 | Q8: 134.99 | R8: 0 | S8: 0 | T8: 0 | U8: 0 | V8: 16 | W8: 687.84 | X8: 0 | Y8: 0 | Z8: 0 | AA8: 0 | AB8: 19 | AC8: 1880.81 | AD8: 26 | AE8: 909.74 | AF8: 0 | AG8: 0 | AH8: 2 | AI8: 11.98 | AJ8: 0 | AK8: 0 | AL8: 0 | AM8: 0 | AN8: 0 | AO8: 0 | AP8: 0 | AQ8: 0 | AR8: 0 | AS8: 0 | AT8: 0 | AU8: 0 | AV8: 0 | AW8: 0 | AX8: 0 | AY8: 0 | AZ8: 5 | BA8: 139.95 | BB8: 0 | BC8: 0 | BD8: 3 | BE8: 227.97
C9: 20 - 26 JAN 2025 | F9: 24 | G9: 3287.76 | H9: 12 | I9: 1235.88 | J9: 20 | K9: 3639.8 | L9: 32 | M9: 5023.68 | N9: 0 | O9: 0 | P9: 2 | Q9: 269.98 | R9: 0 | S9: 0 | T9: 0 | U9: 0 | V9: 14 | W9: 601.86 | X9: 0 | Y9: 0 | Z9: 0 | AA9: 0 | AB9: 18 | AC9: 1777.82 | AD9: 10 | AE9: 349.9 | AF9: 0 | AG9: 0 | AH9: 2 | AI9: 11.98 | AJ9: 0 | AK9: 0 | AL9: 1 | AM9: 49.99 | AN9: 0 | AO9: 0 | AP9: 0 | AQ9: 0 | AR9: 0 | AS9: 0 | AT9: 0 | AU9: 0 | AV9: 20 | AW9: 4149.3 | AX9: 20 | AY9: 4149.3 | AZ9: 3 | BA9: 80.97 | BB9: 0 | BC9: 0 | BD9: 2 | BE9: 151.98
C10: GRAND TOTALS | F10: =SUM(F6:F9) -> 105 | G10: =SUM(G6:G9) -> 14425.95 | H10: =SUM(H6:H9) -> 51 | I10: =SUM(I6:I9) -> 5864.49 | J10: =SUM(J6:J9) -> 84 | K10: =SUM(K6:K9) -> 15287.16 | L10: =SUM(L6:L9) -> 125 | M10: =SUM(M6:M9) -> 18698.81 | ... BE10: =SUM(BE6:BE9) -> 689.9
A11: 45689 | C11: STOCK | F11: Flour | H11: Wsugar | J11: Bsugar | L11: Oil | N11: Eggs | P11: Ricoffy | R11: Wspoon | T11: IcingS | V11: Bpowder | X11: Bicarb | Z11: Cocoa | AB11: Milk | AD11: Carrots | AF11: Ccheese | AH11: Salt | AJ11: Vanilla | AL11: Lemon Juice | AN11: Choc Slabs | AP11: Van Slabs | AR11: Cinnamon | AT11: Red Cherries | AV11: Domes | AX11: Bases | AZ11: Vinegar | BB11: Pecan Nuts | BD11: Cremora
F12: 12.5kg | H12: 10kg | J12: 10kg | L12: 5LITRES | N12: 180 | P12: 750G | R12: 25kg | T12: 25kg | V12: 20kg | X12: 25kg | Z12: 25kg | AB12: 6 x 1litres | AD12: 5kg | AF12: 5kg | AH12: 1kg | AJ12: 3 LITRE | AL12: 2 L | AN12: 20 | AP12: 20 | AR12: 5kg | AT12: 6 KG | AV12: 100 | AX12: 100 | AZ12: 5litres | BB12: 10kg | BD12: 750G
C13: WEEKLY DATES | F13: QUANTITY | G13: TOTALS | H13: QUANTITY | I13: TOTALS | J13: QUANTITY | K13: TOTALS | L13: QUANTITY | M13: TOTALS | N13: QUANTITY | O13: TOTALS | P13: QUANTITY | Q13: TOTALS | R13: QUANTITY | S13: TOTALS | T13: QUANTITY | U13: TOTALS | V13: QUANTITY | W13: TOTALS | X13: QUANTITY | Y13: TOTALS | Z13: QUANTITY | AA13: TOTALS | AB13: QUANTITY | AC13: TOTALS | AD13: QUANTITY | AE13: TOTALS | AF13: QUANTITY | AG13: TOTALS | AH13: QUANTITY | AI13: TOTALS | AJ13: QUANTITY | AK13: TOTALS | AL13: QUANTITY | AM13: TOTALS | AN13: QUANTITY | AO13: TOTALS | AP13: QUANTITY | AQ13: TOTALS | AR13: QUANTITY | AS13: TOTALS | AT13: QUANTITY | AU13: TOTALS | AV13: QUANTITY | AW13: TOTALS | AX13: QUANTITY | AY13: TOTALS | AZ13: QUANTITY | BA13: TOTALS | BB13: QUANTITY | BC13: TOTALS | BD13: QUANTITY | BE13: TOTALS
C14: 27 JAN - 2 FEB 2025 | F14: 27 | G14: 3698.73 | H14: 10 | I14: 1541.9 | J14: 24 | K14: 4367.76 | L14: 34 | M14: 5307.78 | N14: 10 | O14: 6000 | P14: 2 | Q14: 269.98 | R14: 0 | S14: 0 | T14: 0 | U14: 0 | V14: 16 | W14: 687.84 | X14: 0 | Y14: 0 | Z14: 0 | AA14: 0 | AB14: 19 | AC14: 1880.81 | AD14: 20 | AE14: 729.8 | AF14: 0 | AG14: 0 | AH14: 0 | AI14: 0 | AJ14: 0 | AK14: 0 | AL14: 1 | AM14: 49.99 | AN14: 0 | AO14: 0 | AP14: 0 | AQ14: 0 | AR14: 0 | AS14: 0 | AT14: 0 | AU14: 0 | AV14: 15 | AW14: 3578.77 | AX14: 15 | AY14: 3578.77 | AZ14: 3 | BA14: 81.97 | BB14: 0 | BC14: 0 | BD14: 2 | BE14: 151.98 | BG14: ='DAILY WEEKLY EXPENSES STOCK'!#REF! -> #REF!
C15: 3 - 9 FEB 2025 | F15: 26 | G15: 3579.74 | H15: 11 | I15: 1876.89 | J15: 23 | K15: 4185.77 | L15: 34 | M15: 5557.66 | N15: 16 | O15: 8130 | P15: 2 | Q15: 269.98 | R15: 0 | S15: 0 | T15: 0 | U15: 0 | V15: 16 | W15: 687.84 | X15: 0 | Y15: 0 | Z15: 0 | AA15: 0 | AB15: 18 | AC15: 1781.82 | AD15: 27 | AE15: 944.73 | AF15: 0 | AG15: 0 | AH15: 4 | AI15: 23.96 | AJ15: 3 | AK15: 509.8 | AL15: 1 | AM15: 49.99 | AN15: 20 | AO15: 600 | AP15: 20 | AQ15: 600 | AR15: 0 | AS15: 0 | AT15: 0 | AU15: 0 | AV15: 15 | AW15: 3578.77 | AX15: 15 | AY15: 3578.77 | AZ15: 3 | BA15: 81.97 | BB15: 0 | BC15: 0 | BD15: 2 | BE15: 135.98
C16: 10 - 16 FEB 2025 | F16: 30 | G16: 4139.7 | H16: 10 | I16: 1699.9 | J16: 24 | K16: 4367.76 | L16: 33 | M16: 5510.67 | N16: 15 | O16: 5324.94 | P16: 3 | Q16: 404.97 | R16: 0 | S16: 0 | T16: 0 | U16: 0 | V16: 16 | W16: 687.84 | X16: 0 | Y16: 0 | Z16: 0 | AA16: 0 | AB16: 16 | AC16: 1583.84 | AD16: 24 | AE16: 819.76 | AF16: 1 | AG16: 575 | AH16: 0 | AI16: 0 | AJ16: 4 | AK16: 679.8 | AL16: 0 | AM16: 0 | AN16: 0 | AO16: 0 | AP16: 0 | AQ16: 0 | AR16: 0 | AS16: 0 | AT16: 0 | AU16: 0 | AV16: 15 | AW16: 3578.77 | AX16: 15 | AY16: 3578.77 | AZ16: 3 | BA16: 80.97 | BB16: 0 | BC16: 0 | BD16: 3 | BE16: 195.97
C17: 17 - 23 FEB 2025 | F17: 17 | G17: 2328.83 | H17: 4 | I17: 819.96 | J17: 14 | K17: 2547.86 | L17: 16 | M17: 2671.84 | N17: 9 | O17: 3184.95 | P17: 1 | Q17: 134.99 | R17: 6 | S17: 5451 | T17: 18 | U17: 9522 | V17: 8 | W17: 343.92 | X17: 1 | Y17: 772.8 | Z17: 2 | AA17: 8050 | AB17: 16 | AC17: 1285.84 | AD17: 18 | AE17: 629.82 | AF17: 0 | AG17: 0 | AH17: 0 | AI17: 0 | AJ17: 0 | AK17: 0 | AL17: 1 | AM17: 49.99 | AN17: 0 | AO17: 0 | AP17: 0 | AQ17: 0 | AR17: 0 | AS17: 0 | AT17: 2 | AU17: 824.33 | AV17: 10 | AW17: 2385.85 | AX17: 10 | AY17: 2385.85 | AZ17: 2 | BA17: 53.98 | BB17: 0 | BC17: 0 | BD17: 2 | BE17: 151.98
C18: GRAND TOTALS | F18: =SUM(F14:F17) -> 100 | G18: =SUM(G14:G17) -> 13747 | H18: =SUM(H14:H17) -> 35 | I18: =SUM(I14:I17) -> 5938.65 | J18: =SUM(J14:J17) -> 85 | K18: =SUM(K14:K17) -> 15469.15 | L18: =SUM(L14:L17) -> 117 | M18: =SUM(M14:M17) -> 19047.95 | ... BE18: =SUM(BE14:BE17) -> 635.91
A19: 45717 | C19: STOCK | F19: Flour | H19: Wsugar | J19: Bsugar | L19: Oil | N19: Eggs | P19: Ricoffy | R19: Wspoon | T19: IcingS | V19: Bpowder | X19: Bicarb | Z19: Cocoa | AB19: Milk | AD19: Carrots | AF19: Ccheese | AH19: Salt | AJ19: Vanilla | AL19: Lemon Juice | AN19: Choc Slabs | AP19: Van Slabs | AR19: Cinnamon | AT19: Red Cherries | AV19: Domes | AX19: Bases | AZ19: Vinegar | BB19: Pecan Nuts | BD19: Cremora
F20: 12.5kg | H20: 10kg | J20: 10kg | L20: 5LITRES | N20: 180 | P20: 750G | R20: 25kg | T20: 25kg | V20: 20kg | X20: 25kg | Z20: 25kg | AB20: 6 x 1litres | AD20: 5kg | AF20: 5kg | AH20: 1kg | AJ20: 3 LITRE | AL20: 2 L | AN20: 20 | AP20: 20 | AR20: 5kg | AT20: 6 KG | AV20: 100 | AX20: 100 | AZ20: 5litres | BB20: 10kg | BD20: 750G
C21: WEEKLY DATES | F21: QUANTITY | G21: TOTALS | H21: QUANTITY | I21: TOTALS | J21: QUANTITY | K21: TOTALS | L21: QUANTITY | M21: TOTALS | N21: QUANTITY | O21: TOTALS | P21: QUANTITY | Q21: TOTALS | R21: QUANTITY | S21: TOTALS | T21: QUANTITY | U21: TOTALS | V21: QUANTITY | W21: TOTALS | X21: QUANTITY | Y21: TOTALS | Z21: QUANTITY | AA21: TOTALS | AB21: QUANTITY | AC21: TOTALS | AD21: QUANTITY | AE21: TOTALS | AF21: QUANTITY | AG21: TOTALS | AH21: QUANTITY | AI21: TOTALS | AJ21: QUANTITY | AK21: TOTALS | AL21: QUANTITY | AM21: TOTALS | AN21: QUANTITY | AO21: TOTALS | AP21: QUANTITY | AQ21: TOTALS | AR21: QUANTITY | AS21: TOTALS | AT21: QUANTITY | AU21: TOTALS | AV21: QUANTITY | AW21: TOTALS | AX21: QUANTITY | AY21: TOTALS | AZ21: QUANTITY | BA21: TOTALS | BB21: QUANTITY | BC21: TOTALS | BD21: QUANTITY | BE21: TOTALS
C22: 24 FEB - 2 MAR 2025 | F22: 28 | G22: 3835.72 | H22: 8 | I22: 1639.92 | J22: 23 | K22: 4185.77 | L22: 32 | M22: 5379.8 | N22: 20 | O22: 6949.94 | P22: 1 | Q22: 134.99 | R22: 0 | S22: 0 | T22: 15 | U22: 7935 | V22: 14 | W22: 601.86 | X22: 0 | Y22: 0 | Z22: 0 | AA22: 0 | AB22: 19 | AC22: 1880.81 | AD22: 16 | AE22: 639.84 | AF22: 1 | AG22: 575 | AH22: 0 | AI22: 0 | AJ22: 5 | AK22: 849.75 | AL22: 0 | AM22: 0 | AN22: 20 | AO22: 600 | AP22: 20 | AQ22: 600 | AR22: 0 | AS22: 0 | AT22: 0 | AU22: 0 | AV22: 15 | AW22: 3578.77 | AX22: 15 | AY22: 3578.77 | AZ22: 3 | BA22: 80.97 | BB22: 0 | BC22: 0 | BD22: 3 | BE22: 227.97
C23: 3 - 9 MAR 2025 | F23: 32 | G23: 4419.68 | H23: 8 | I23: 1639.92 | J23: 27 | K23: 4913.73 | L23: 36 | M23: 6011.64 | N23: 17 | O23: 6074.96 | P23: 2 | Q23: 289.98 | R23: 12 | S23: 1886.9 | T23: 11 | U23: 6170.95 | V23: 14 | W23: 601.86 | X23: 0 | Y23: 0 | Z23: 0 | AA23: 0 | AB23: 20 | AC23: 1979.8 | AD23: 28 | AE23: 1123.72 | AF23: 0 | AG23: 0 | AH23: 0 | AI23: 0 | AJ23: 0 | AK23: 0 | AL23: 1 | AM23: 49.99 | AN23: 0 | AO23: 0 | AP23: 0 | AQ23: 0 | AR23: 0 | AS23: 0 | AT23: 0 | AU23: 0 | AV23: 0 | AW23: 0 | AX23: 0 | AY23: 0 | AZ23: 3 | BA23: 80.97 | BB23: 0 | BC23: 0 | BD23: 2 | BE23: 151.98
C24: 10 - 16 MAR 2025 | F24: 25 | G24: 3499.75 | H24: 6 | I24: 1229.94 | J24: 16 | K24: 2935.9 | L24: 28 | M24: 4711.84 | N24: 16 | O24: 5999.94 | P24: 2 | Q24: 289.99 | R24: 0 | S24: 0 | T24: 0 | U24: 0 | V24: 14 | W24: 601.86 | X24: 0 | Y24: 0 | Z24: 0 | AA24: 0 | AB24: 16 | AC24: 1627.84 | AD24: 21 | AE24: 944.79 | AF24: 0 | AG24: 0 | AH24: 2 | AI24: 11.98 | AJ24: 0 | AK24: 0 | AL24: 1 | AM24: 49.99 | AN24: 0 | AO24: 0 | AP24: 0 | AQ24: 0 | AR24: 0 | AS24: 0 | AT24: 0 | AU24: 0 | AV24: 10 | AW24: 2385.85 | AX24: 10 | AY24: 2385.85 | AZ24: 3 | BA24: 80.97 | BB24: 0 | BC24: 0 | BD24: 1 | BE24: 75.99
C25: 17 - 23 MAR 2025 | F25: 22 | G25: 3079.78 | H25: 6 | I25: 1229.94 | J25: 20 | K25: 3639.8 | L25: 26 | M25: 4401.74 | N25: 47 | O25: 5934.79 | P25: 2 | Q25: 289.98 | R25: 0 | S25: 0 | T25: 0 | U25: 0 | V25: 16 | W25: 729.84 | X25: 0 | Y25: 0 | Z25: 0 | AA25: 0 | AB25: 18 | AC25: 1781.82 | AD25: 16 | AE25: 719.84 | AF25: 0 | AG25: 0 | AH25: 0 | AI25: 0 | AJ25: 0 | AK25: 0 | AL25: 0 | AM25: 0 | AN25: 0 | AO25: 0 | AP25: 0 | AQ25: 0 | AR25: 0 | AS25: 0 | AT25: 0 | AU25: 0 | AV25: 15 | AW25: 3578.77 | AX25: 15 | AY25: 3578.77 | AZ25: 2 | BA25: 53.98 | BB25: 0 | BC25: 0 | BD25: 2 | BE25: 154.98
C26: GRAND TOTALS | F26: =SUM(F22:F25) -> 107 | G26: =SUM(G22:G25) -> 14834.93 | H26: =SUM(H22:H25) -> 28 | I26: =SUM(I22:I25) -> 5739.72 | J26: =SUM(J22:J25) -> 86 | K26: =SUM(K22:K25) -> 15675.2 | L26: =SUM(L22:L25) -> 122 | M26: =SUM(M22:M25) -> 20505.02 | ... BE26: =SUM(BE22:BE25) -> 610.92
A27: 45748 | C27: STOCK | F27: Flour | H27: Wsugar | J27: Bsugar | L27: Oil | N27: Eggs | P27: Ricoffy | R27: Wspoon | T27: IcingS | V27: Bpowder | X27: Bicarb | Z27: Cocoa | AB27: Milk | AD27: Carrots | AF27: Ccheese | AH27: Salt | AJ27: Vanilla | AL27: Lemon Juice | AN27: Choc Slabs | AP27: Van Slabs | AR27: Cinnamon | AT27: Red Cherries | AV27: Domes | AX27: Bases | AZ27: Vinegar | BB27: Pecan Nuts | BD27: Cremora
F28: 12.5kg | H28: 10kg | J28: 10kg | L28: 5LITRES | N28: 180 | P28: 750G | R28: 25kg | T28: 25kg | V28: 20kg | X28: 25kg | Z28: 25kg | AB28: 6 x 1litres | AD28: 5kg | AF28: 5kg | AH28: 1kg | AJ28: 3 LITRE | AL28: 2 L | AN28: 20 | AP28: 20 | AR28: 5kg | AT28: 6 KG | AV28: 100 | AX28: 100 | AZ28: 5litres | BB28: 10kg | BD28: 750G
C29: WEEKLY DATES | F29: QUANTITY | G29: TOTALS | H29: QUANTITY | I29: TOTALS | J29: QUANTITY | K29: TOTALS | L29: QUANTITY | M29: TOTALS | N29: QUANTITY | O29: TOTALS | P29: QUANTITY | Q29: TOTALS | R29: QUANTITY | S29: TOTALS | T29: QUANTITY | U29: TOTALS | V29: QUANTITY | W29: TOTALS | X29: QUANTITY | Y29: TOTALS | Z29: QUANTITY | AA29: TOTALS | AB29: QUANTITY | AC29: TOTALS | AD29: QUANTITY | AE29: TOTALS | AF29: QUANTITY | AG29: TOTALS | AH29: QUANTITY | AI29: TOTALS | AJ29: QUANTITY | AK29: TOTALS | AL29: QUANTITY | AM29: TOTALS | AN29: QUANTITY | AO29: TOTALS | AP29: QUANTITY | AQ29: TOTALS | AR29: QUANTITY | AS29: TOTALS | AT29: QUANTITY | AU29: TOTALS | AV29: QUANTITY | AW29: TOTALS | AX29: QUANTITY | AY29: TOTALS | AZ29: QUANTITY | BA29: TOTALS | BB29: QUANTITY | BC29: TOTALS | BD29: QUANTITY | BE29: TOTALS
C30: 24 - 30 MAR 2025 | F30: 30 | G30: 4136.7 | H30: 8 | I30: 1664.92 | J30: 24 | K30: 4367.76 | L30: 32 | M30: 5494.77 | N30: 44 | O30: 7539.82 | P30: 3 | Q30: 434.97 | R30: 0 | S30: 0 | T30: 0 | U30: 0 | V30: 14 | W30: 601.86 | X30: 0 | Y30: 0 | Z30: 1 | AA30: 4358 | AB30: 17 | AC30: 1682.83 | AD30: 28 | AE30: 1259.72 | AF30: 1 | AG30: 575 | AH30: 0 | AI30: 0 | AJ30: 5 | AK30: 849.75 | AL30: 1 | AM30: 43.99 | AN30: 20 | AO30: 300 | AP30: 20 | AQ30: 300 | AR30: 0 | AS30: 0 | AT30: 0 | AU30: 0 | AV30: 15 | AW30: 3578.77 | AX30: 15 | AY30: 3578.77 | AZ30: 4 | BA30: 107.96 | BB30: 0 | BC30: 0 | BD30: 1 | BE30: 75.99
C31: 31 MAR - 6 APR 2025 | F31: 12 | G31: 1655.88 | H31: 4 | I31: 819.96 | J31: 8 | K31: 1455.92 | L31: 12 | M31: 2075.88 | N31: 20 | O31: 3675 | P31: 0 | Q31: 0 | R31: 0 | S31: 0 | T31: 0 | U31: 0 | V31: 8 | W31: 343.92 | X31: 0 | Y31: 0 | Z31: 0 | AA31: 0 | AB31: 8 | AC31: 791.92 | AD31: 23 | AE31: 1149.77 | AF31: 0 | AG31: 0 | AH31: 0 | AI31: 0 | AJ31: 0 | AK31: 0 | AL31: 0 | AM31: 0 | AN31: 0 | AO31: 0 | AP31: 0 | AQ31: 0 | AR31: 0 | AS31: 0 | AT31: 0 | AU31: 0 | AV31: 15 | AW31: 3578.77 | AX31: 15 | AY31: 3578.77 | AZ31: 1 | BA31: 26.99 | BB31: 0 | BC31: 0 | BD31: 0 | BE31: 0
C32: 7 - 13 APR 2025 | F32: 23 | G32: 3150.77 | H32: 6 | I32: 1229.94 | J32: 21 | K32: 3821.79 | L32: 27 | M32: 4670.73 | N32: 45 | O32: 5849.55 | P32: 2 | Q32: 289.98 | R32: 22 | S32: 3763.12 | T32: 0 | U32: 0 | V32: 8 | W32: 413.94 | X32: 0 | Y32: 0 | Z32: 0 | AA32: 0 | AB32: 16 | AC32: 1583.84 | AD32: 22 | AE32: 784.78 | AF32: 1 | AG32: 548.32 | AH32: 0 | AI32: 0 | AJ32: 0 | AK32: 0 | AL32: 0 | AM32: 0 | AN32: 0 | AO32: 0 | AP32: 0 | AQ32: 0 | AR32: 0 | AS32: 0 | AT32: 0 | AU32: 0 | AV32: 15 | AW32: 3578.77 | AX32: 15 | AY32: 3578.77 | AZ32: 4 | BA32: 81.97 | BB32: 0 | BC32: 0 | BD32: 2 | BE32: 151.98
C33: 14 - 20 APR 2025 | F33: 40 | G33: 5479.6 | H33: 11 | I33: 2254.89 | J33: 34 | K33: 6187.66 | L33: 46 | M33: 7957.54 | N33: 40 | O33: 9854.79 | P33: 2 | Q33: 434.98 | R33: 0 | S33: 0 | T33: 0 | U33: 0 | V33: 24 | W33: 1783.76 | X33: 0 | Y33: 0 | Z33: 0 | AA33: 0 | AB33: 25 | AC33: 2474.75 | AD33: 38 | AE33: 1899.62 | AF33: 0 | AG33: 0 | AH33: 0 | AI33: 0 | AJ33: 0 | AK33: 0 | AL33: 1 | AM33: 49.99 | AN33: 0 | AO33: 0 | AP33: 0 | AQ33: 0 | AR33: 0 | AS33: 0 | AT33: 0 | AU33: 0 | AV33: 15 | AW33: 3578.77 | AX33: 15 | AY33: 3578.77 | AZ33: 5 | BA33: 139.95 | BB33: 0 | BC33: 0 | BD33: 1 | BE33: 75.99
C34: GRAND TOTALS | F34: =SUM(F30:F33) -> 105 | G34: =SUM(G30:G33) -> 14422.95 | H34: =SUM(H30:H33) -> 29 | I34: =SUM(I30:I33) -> 5969.71 | J34: =SUM(J30:J33) -> 87 | K34: =SUM(K30:K33) -> 15833.13 | L34: =SUM(L30:L33) -> 117 | M34: =SUM(M30:M33) -> 20198.92 | ... BE34: =SUM(BE30:BE33) -> 303.96
A35: 45778 | C35: STOCK | F35: Flour | H35: Wsugar | J35: Bsugar | L35: Oil | N35: Eggs | P35: Ricoffy | R35: Wspoon | T35: IcingS | V35: Bpowder | X35: Bicarb | Z35: Cocoa | AB35: Milk | AD35: Carrots | AF35: Ccheese | AH35: Salt | AJ35: Vanilla | AL35: Lemon Juice | AN35: Choc Slabs | AP35: Van Slabs | AR35: Cinnamon | AT35: Red Cherries | AV35: Domes | AX35: Bases | AZ35: Vinegar | BB35: Pecan Nuts | BD35: Cremora
F36: 12.5kg | H36: 10kg | J36: 10kg | L36: 5LITRES | N36: 180 | P36: 750G | R36: 25kg | T36: 25kg | V36: 20kg | X36: 25kg | Z36: 25kg | AB36: 6 x 1litres | AD36: 5kg | AF36: 5kg | AH36: 1kg | AJ36: 3 LITRE | AL36: 2 L | AN36: 20 | AP36: 20 | AR36: 5kg | AT36: 6 KG | AV36: 100 | AX36: 100 | AZ36: 5litres | BB36: 10kg | BD36: 750G
C37: WEEKLY DATES | F37: QUANTITY | G37: TOTALS | H37: QUANTITY | I37: TOTALS | J37: QUANTITY | K37: TOTALS | L37: QUANTITY | M37: TOTALS | N37: QUANTITY | O37: TOTALS | P37: QUANTITY | Q37: TOTALS | R37: QUANTITY | S37: TOTALS | T37: QUANTITY | U37: TOTALS | V37: QUANTITY | W37: TOTALS | X37: QUANTITY | Y37: TOTALS | Z37: QUANTITY | AA37: TOTALS | AB37: QUANTITY | AC37: TOTALS | AD37: QUANTITY | AE37: TOTALS | AF37: QUANTITY | AG37: TOTALS | AH37: QUANTITY | AI37: TOTALS | AJ37: QUANTITY | AK37: TOTALS | AL37: QUANTITY | AM37: TOTALS | AN37: QUANTITY | AO37: TOTALS | AP37: QUANTITY | AQ37: TOTALS | AR37: QUANTITY | AS37: TOTALS | AT37: QUANTITY | AU37: TOTALS | AV37: QUANTITY | AW37: TOTALS | AX37: QUANTITY | AY37: TOTALS | AZ37: QUANTITY | BA37: TOTALS | BB37: QUANTITY | BC37: TOTALS | BD37: QUANTITY | BE37: TOTALS
C38: 21 - 27 APR 2025 | F38: 26 | G38: 3615.74 | H38: 8 | I38: 1639.92 | J38: 20 | K38: 3639.8 | L38: 26 | M38: 4497.74 | N38: 48 | O38: 6143.67 | P38: 3 | Q38: 454.97 | R38: 0 | S38: 0 | T38: 12 | U38: 5155.08 | V38: 4 | W38: 171.96 | X38: 0 | Y38: 0 | Z38: 0 | AA38: 0 | AB38: 19 | AC38: 1880.81 | AD38: 24 | AE38: 1439.76 | AF38: 0 | AG38: 0 | AH38: 0 | AI38: 0 | AJ38: 4 | AK38: 759.8 | AL38: 1 | AM38: 43.99 | AN38: 0 | AO38: 0 | AP38: 0 | AQ38: 0 | AR38: 0 | AS38: 0 | AT38: 0 | AU38: 0 | AV38: 15 | AW38: 3578.77 | AX38: 15 | AY38: 3578.77 | AZ38: 7 | BA38: 155.93 | BB38: 0 | BC38: 0 | BD38: 2 | BE38: 139.98
C39: 28 APR - 4 MAY 2025 | F39: 34 | G39: 4711.66 | H39: 8 | I39: 1639.92 | J39: 27 | K39: 4949.73 | L39: 36 | M39: 6227.64 | N39: 69 | O39: 8843.7 | P39: 3 | Q39: 434.97 | R39: 0 | S39: 0 | T39: 0 | U39: 0 | V39: 18 | W39: 773.82 | X39: 0 | Y39: 0 | Z39: 0 | AA39: 0 | AB39: 24 | AC39: 2375.76 | AD39: 14 | AE39: 769.86 | AF39: 0 | AG39: 0 | AH39: 0 | AI39: 0 | AJ39: 0 | AK39: 0 | AL39: 0 | AM39: 0 | AN39: 0 | AO39: 0 | AP39: 0 | AQ39: 0 | AR39: 1 | AS39: 500 | AT39: 0 | AU39: 0 | AV39: 15 | AW39: 3578.77 | AX39: 15 | AY39: 3578.77 | AZ39: 3 | BA39: 83.97 | BB39: 0 | BC39: 0 | BD39: 2 | BE39: 159.98
C42: GRAND TOTALS | F42: =SUM(F38:F41) -> 60 | G42: =SUM(G38:G41) -> 8327.4 | H42: =SUM(H38:H41) -> 16 | I42: =SUM(I38:I41) -> 3279.84 | J42: =SUM(J38:J41) -> 47 | K42: =SUM(K38:K41) -> 8589.53 | L42: =SUM(L38:L41) -> 62 | M42: =SUM(M38:M41) -> 10725.38 | ... BE42: =SUM(BE38:BE41) -> 299.96
A43: 45809 | C43: STOCK | F43: Flour | H43: Wsugar | J43: Bsugar | L43: Oil | N43: Eggs | P43: Ricoffy | R43: Wspoon | T43: IcingS | V43: Bpowder | X43: Bicarb | Z43: Cocoa | AB43: Milk | AD43: Carrots | AF43: Ccheese | AH43: Salt | AJ43: Vanilla | AL43: Lemon Juice | AN43: Choc Slabs | AP43: Van Slabs | AR43: Cinnamon | AT43: Red Cherries | AV43: Domes | AX43: Bases | AZ43: Vinegar | BB43: Pecan Nuts | BD43: Cremora
...

Sheet EXPENSE DAILY
A1: EXPENSES
A2: DATE | B2: 45657
A3: SLIP NUMBER | B3: AMOUNT | C3: VAT | D3: Shop
A4: 1 | B4: 79 | C4: 10.3 | D4: TOLL GATE
A5: 2 | B5: 79 | C5: 10.3 | D5: TOLL GATE
A6: 3 | B6: 744.67 | D6: DIESEL
A7: 4 | B7: 1000 | D7: DIESEL
A8: 5 | B8: 3176 | C8: 414.26 | D8: BAKERSBIN
A9: 6 | B9: 252 | D9: BACK 2 BASICS
A10: 7 | B10: 5765.73 | C10: 413.37 | D10: WASI
A11: 8 | B11: 286.9 | C11: 2.32 | D11: SHOPRITE
A12: 9 | B12: 990.23 | C12: 129.16 | D12: PNP
A13: 10 | B13: 570 | D13: SOAP CENTRE
A14: 11 | B14: 90 | D14: TBANTU
A15: 12 | B15: 6000 | D15: HEIDEL EGGS
B16: =SUM(B4:B15) -> 19033.53 | C16: =SUM(C4:C15) -> 979.71
A18: EXPENSES
A19: DATE | B19: 45658
A20: SLIP NUMBER | B20: AMOUNT | C20: VAT | D20: Shop
A21: 1 | B21: 300 | D21: DIESEL
A22: 2 | B22: 800 | D22: DIESEL
B23: =SUM(B21:B22) -> 1100 | C23: =SUM(C21:C22) -> 0
A25: EXPENSES
A26: DATE | B26: 45659
A27: SLIP NUMBER | B27: AMOUNT | C27: VAT | D27: Shop
A28: 1 | B28: 300 | D28: DIESEL
A29: 2 | B29: 131.98 | C29: 17.21 | D29: PNP
A30: 3 | B30: 6147.5 | C30: 593.35 | D30: WASI
A31: 4 | B31: 7587.25 | C31: 989.64 | D31: WASI
B32: =SUM(B28:B31) -> 14166.73 | C32: =SUM(C28:C31) -> 1600.2
A34: EXPENSES
A35: DATE | B35: 45660
A36: SLIP NUMBER | B36: AMOUNT | C36: VAT | D36: Shop
A37: 1 | B37: 704.64 | D37: DIESEL
A38: 2 | B38: 469.89 | C38: 11.34 | D38: SHOPRITE
B39: =SUM(B37:B38) -> 1174.53 | C39: =SUM(C37:C38) -> 11.34
A41: EXPENSES
A42: DATE | B42: 45661
A43: SLIP NUMBER | B43: AMOUNT | C43: VAT | D43: Shop
A44: 1 | B44: 750 | D44: DIESEL
...

Sheet DAILY INCOME EXPENSE
A1: MONTH
A2: 45658 | G2: 45689 | M2: 45717 | S2: 45748 | Y2: 45778 | AE2: 45809 | AK2: 45839 | AQ2: 45870 | AW2: 45901 | BC2: 45931 | BI2: 45962 | BO2: 45992
A3: DATE | B3: INCOME | C3: INCOME VAT | D3: EXPENSES | E3: EXPENSES VAT | G3: DATE | H3: INCOME | I3: INCOME VAT | J3: EXPENSES | K3: EXPENSES VAT | M3: DATE | N3: INCOME | O3: INCOME VAT | P3: EXPENSES | Q3: EXPENSES VAT | S3: DATE | T3: INCOME | U3: INCOME VAT | V3: EXPENSES | W3: EXPENSES VAT | Y3: DATE | Z3: INCOME | AA3: INCOME VAT | AB3: EXPENSES | AC3: EXPENSES VAT | AE3: DATE | AF3: INCOME | AG3: INCOME VAT | AH3: EXPENSES | AI3: EXPENSES VAT | AK3: DATE | AL3: INCOME | AM3: INCOME VAT | AN3: EXPENSES | AO3: EXPENSES VAT | AQ3: DATE | AR3: INCOME | AS3: INCOME VAT | AT3: EXPENSES | AU3: EXPENSES VAT | AW3: DATE | AX3: INCOME | AY3: INCOME VAT | AZ3: EXPENSES | BA3: EXPENSES VAT | BC3: DATE | BD3: INCOME | BE3: INCOME VAT | BF3: EXPENSES | BG3: EXPENSES VAT | BI3: DATE | BJ3: INCOME | BK3: INCOME VAT | BL3: EXPENSES | BM3: EXPENSES VAT | BO3: DATE | BP3: INCOME | BQ3: INCOME VAT | BR3: EXPENSES | BS3: EXPENSES VAT
A4: 1 | B4: 26962 | C4: =238.8+238.8+356.4+209.4+209.41+429.2 -> 1682.01 | D4: 1100 | G4: 1 | H4: 21137 | I4: 358.2+928.8 | J4: 14175.16 | K4: 565.91 | M4: 1 | N4: 0 | O4: 0 | P4: 10379.54 | Q4: 566.36 | S4: 1 | T4: 32648.5 | U4: =1128+773.4+773.4+773.4+773.4 -> 4221.6 | V4: =1713.5+8334.88 -> 10048.38 | W4: =223.5+516.7 -> 740.2 | Y4: 1 | Z4: 3429.3 | AA4: =477.3 -> 477.3 | AB4: 19634.23 | AC4: 1569.43 | AE4: 1 | AK4: 1 | AQ4: 1 | AW4: 1 | BC4: 1 | BI4: 1 | BO4: 1
A5: 2 | B5: 0 | C5: 0 | D5: 14166.73 | E5: 1600.2 | G5: 2 | M5: 2 | S5: 2 | T5: 28103.6 | U5: =536.4+356.4+297.6+1249.2 -> 2439.6 | V5: 800 | Y5: 2 | Z5: 36639.2 | AA5: =775.2+415.2+477.6+861.6+861.6 -> 3391.2 | AB5: 9294.47 | AC5: 421.77 | AE5: 2 | AK5: 2 | AQ5: 2 | AW5: 2 | BC5: 2 | BI5: 2 | BO5: 2
A6: 3 | B6: 34781.6 | C6: =238.8+238.8+297.6+418.8+1503.6 -> 2697.6 | D6: 1174.53 | E6: 11.34 | G6: 3 | H6: 28372.8 | I6: =536.4+356.4+477.6 -> 1370.4 | J6: 10025.85 | K6: 858.38 | M6: 3 | N6: 30372.8 | O6: =477.6+356.4+297.6+1069.2 -> 2200.8 | P6: 7862.62 | Q6: 519.82 | S6: 3 | T6: 3781.2 | U6: 508.8 | V6: =16537+9381.7 -> 25918.7 | W6: =2157+956.32 -> 3113.32 | Y6: 3 | Z6: 18564.2 | AA6: =878.1+878.1 -> 1756.2 | AB6: 26579.44 | AC6: 490.91 | AE6: 3 | AK6: 3 | AQ6: 3 | AW6: 3 | BC6: 3 | BI6: 3 | BO6: 3
A7: 4 | B7: 14519.9 | C7: =1025.1+868.8 -> 1893.9 | D7: 26186.48 | E7: 507.41 | G7: 4 | H7: 33362.6 | I7: =1190.4+1131.6+804.6+834+834+712.8 -> 5507.4 | J7: 8633.4 | K7: 678.36 | M7: 4 | N7: 32319.6 | O7: =995.7+789.9+834+834+744 -> 4197.6 | P7: 15362.72 | Q7: 1336.34 | S7: 4 | T7: 34996 | U7: =775.2+415.2+477.6+1488 -> 3156 | V7: 4660.56 | W7: 463.8 | Y7: 4 | Z7: 0 | AB7: 54.99 | AC7: 7.18 | AE7: 4 | AK7: 4 | AQ7: 4 | AW7: 4 | BC7: 4 | BI7: 4 | BO7: 4
A8: 5 | B8: 0 | C8: 0 | D8: 408.15 | E8: 23.35 | G8: 5 | H8: 29432.8 | I8: =536.4+356.4+418.8+1249.2 -> 2560.8 | J8: =24863+800 -> 25663 | K8: 3243 | M8: 5 | N8: 25572.8 | O8: =477.6+356.4+297.6+1069.2 -> 2200.8 | P8: 800 | S8: 5 | T8: 0 | U8: 0 | V8: 992.98 | Y8: 5 | Z8: 28898.2 | AB8: 13380.48 | AC8: 704.79 | AE8: 5 | AK8: 5 | AQ8: 5 | AW8: 5 | BC8: 5 | BI8: 5 | BO8: 5
A9: 6 | B9: 29475.2 | C9: =537.3+355.5+493.2+1295.1 -> 2681.1 | D9: 25261.43 | E9: 916.5 | G9: 6 | H9: 7510.8 | I9: 418.8 | J9: 17671.61 | K9: 1654.54 | M9: 6 | N9: 5910.8 | O9: 418.8 | P9: =4358.5+8885.69 -> 13244.19 | Q9: =568.5+514.16 -> 1082.66 | S9: 6 | T9: 13697.2 | U9: =1069.2 -> 1069.2 | V9: 6101.77 | W9: 204.58 | Y9: 6 | Z9: 44311.8 | AB9: 5470.97 | AC9: 205.93 | AE9: 6 | AK9: 6 | AQ9: 6 | AW9: 6 | BC9: 6 | BI9: 6 | BO9: 6
A10: 7 | B10: 28294.8 | C10: =1069.2+625.5+625.5+625.5 -> 2945.7 | D10: =28014+16896.39 -> 44910.39 | E10: =3654+607.8 -> 4261.8 | G10: 7 | H10: 30825.2 | I10: =595.2+356.4+477.6+1488 -> 2917.2 | J10: 6800 | M10: 7 | N10: 31485.2 | O10: =654+356.4+477.6+1249.2 -> 2737.2 | P10: 20437.03 | Q10: 68.95 | S10: 7 | T10: 23923.6 | U10: =238.8+238.8+178.2+178.2+148.8+148.8+564+564 -> 2259.6 | V10: 8823.39 | W10: 758.34 | Y10: 7 | Z10: 20038.6 | AB10: 800.08 | AE10: 7 | AK10: 7 | AQ10: 7 | AW10: 7 | BC10: 7 | BI10: 7 | BO10: 7
A11: WEEKLY TOTALS | B11: =SUM(B4:B10) -> 134033.5 | C11: =SUM(C4:C10) -> 11900.31 | D11: =SUM(D4:D10) -> 113207.71 | E11: =SUM(E4:E10) -> 7320.6 | G11: WEEKLY TOTALS | H11: =SUM(H4:H10) -> 150641.2 | I11: =SUM(I4:I10) -> 12774.6 | J11: =SUM(J4:J10) -> 82969.02 | K11: =SUM(K4:K10) -> 7000.19 | M11: WEEKLY TOTALS | N11: =SUM(N4:N10) -> 125661.2 | O11: =SUM(O4:O10) -> 11755.2 | P11: =SUM(P4:P10) -> 68086.1 | Q11: =SUM(Q4:Q10) -> 3574.13 | S11: WEEKLY TOTALS | T11: =SUM(T4:T10) -> 137150.1 | U11: =SUM(U4:U10) -> 13654.8 | V11: =SUM(V4:V10) -> 57345.78 | W11: =SUM(W4:W10) -> 5280.24 | Y11: WEEKLY TOTALS | Z11: =SUM(Z4:Z10) -> 151881.3 | AA11: =SUM(AA4:AA10) -> 5624.7 | AB11: =SUM(AB4:AB10) -> 75214.66 | AC11: =SUM(AC4:AC10) -> 3400.01 | AE11: WEEKLY TOTALS | AF11: =SUM(AF4:AF10) -> 0 | AG11: =SUM(AG4:AG10) -> 0 | AH11: =SUM(AH4:AH10) -> 0 | AI11: =SUM(AI4:AI10) -> 0 | AK11: WEEKLY TOTALS | AL11: =SUM(AL4:AL10) -> 0 | AM11: =SUM(AM4:AM10) -> 0 | AN11: =SUM(AN4:AN10) -> 0 | AO11: =SUM(AO4:AO10) -> 0 | AQ11: WEEKLY TOTALS | AR11: =SUM(AR4:AR10) -> 0 | AS11: =SUM(AS4:AS10) -> 0 | AT11: =SUM(AT4:AT10) -> 0 | AU11: =SUM(AU4:AU10) -> 0 | AW11: WEEKLY TOTALS | AX11: =SUM(AX4:AX10) -> 0 | AY11: =SUM(AY4:AY10) -> 0 | AZ11: =SUM(AZ4:AZ10) -> 0 | BA11: =SUM(BA4:BA10) -> 0 | BC11: WEEKLY TOTALS | BD11: =SUM(BD4:BD10) -> 0 | BE11: =SUM(BE4:BE10) -> 0 | BF11: =SUM(BF4:BF10) -> 0 | BG11: =SUM(BG4:BG10) -> 0 | BI11: WEEKLY TOTALS | BJ11: =SUM(BJ4:BJ10) -> 0 | BK11: =SUM(BK4:BK10) -> 0 | BL11: =SUM(BL4:BL10) -> 0 | BM11: =SUM(BM4:BM10) -> 0 | BO11: WEEKLY TOTALS | BP11: =SUM(BP4:BP10) -> 0 | BQ11: =SUM(BQ4:BQ10) -> 0 | BR11: =SUM(BR4:BR10) -> 0 | BS11: =SUM(BS4:BS10) -> 0
A12: 8 | B12: 24087 | C12: =537.3+355.5+449.1+1025.1 -> 2367 | D12: 800 | E12: 0 | G12: 8 | H12: 0 | I12: 0 | J12: 19627.7 | K12: 113.84 | M12: 8 | N12: 0 | O12: 0 | P12: 7434.59 | Q12: 667.61 | S12: 8 | T12: 26792.7 | U12: =626.4+949.8+655.8+655.8+670.5 -> 3558.3 | V12: =16547.13+9858.26 -> 26405.39 | W12: =2158.33+979.69 -> 3138.02 | Y12: 8 | Z12: 3661.6 | AB12: 8387.48 | AC12: 431.08 | AE12: 8 | AK12: 8 | AQ12: 8 | AW12: 8 | BC12: 8 | BI12: 8 | BO12: 8
A13: 9 | B13: 9075.4 | C13: =534.6+346.2 -> 880.8 | D13: 20124.8 | E13: 2191.01 | G13: 9 | H13: 0 | I13: 0 | J13: 8897.28 | K13: 638.79 | M13: 9 | N13: 8197.2 | O13: =1069.2 -> 1069.2 | P13: 10892.15 | Q13: 768.92 | S13: 9 | T13: 31422.8 | U13: =477.6+266.4+297.6+1069.2 -> 2110.8 | V13: 800 | Y13: 9 | AE13: 9 | AK13: 9 | AQ13: 9 | AW13: 9 | BC13: 9 | BI13: 9 | BO13: 9
A14: 10 | B14: 37083.9 | C14: =402.3+449.1+1430.1 -> 2281.5 | D14: 804.72 | E14: 0 | G14: 10 | H14: 33207.4 | I14: =253.5+253.5+178.2+178.2+238.8+238.8+1190.4+744 -> 3275.4 | J14: 10043.06 | K14: 637.24 | M14: 10 | N14: 35952.8 | O14: =536.4+356.4+297.6+1190.4 -> 2380.8 | P14: 11246.51 | Q14: 660.13 | S14: 10 | T14: 25519 | U14: 508.8 | V14: 20637.15 | W14: 1854.45 | Y14: 10 | AE14: 10 | AK14: 10 | AQ14: 10 | AW14: 10 | BC14: 10 | BI14: 10 | BO14: 10
A15: 11 | B15: 3300 | C15: =716.4 -> 716.4 | D15: 10078.14 | E15: 345.65 | G15: 11 | H15: 33136.1 | I15: =1131.6+804.6+834+834 -> 3604.2 | J15: 12317.61 | K15: 793.38 | M15: 11 | N15: 29573.4 | O15: =953.4+714.6+714.6+714.6+744 -> 3841.2 | P15: =19333.8+12400.5 -> 31734.3 | Q15: =2521.8+1077.46 -> 3599.26 | S15: 11 | T15: 25519 | U15: =597+356.4+477.6+1128 -> 2559 | V15: 15620 | Y15: 11 | AE15: 11 | AK15: 11 | AQ15: 11 | AW15: 11 | BC15: 11 | BI15: 11 | BO15: 11
A16: 12 | B16: 0 | C16: 0 | D16: 7158.41 | E16: 502.32 | G16: 12 | H16: 28480.4 | I16: =418.8+356.4+418.8+1190.4 -> 2384.4 | J16: 4590.61 | K16: 342.11 | M16: 12 | N16: 25052.8 | O16: =536.4+356.4+297.6+1190.4 -> 2380.8 | P16: 1400 | S16: 12 | T16: 0 | V16: 6942.5 | W16: 385.92 | Y16: 12 | AE16: 12 | AK16: 12 | AQ16: 12 | AW16: 12 | BC16: 12 | BI16: 12 | BO16: 12
A17: 13 | B17: 26805.8 | C17: =537.3+402.3+493.2+981 -> 2413.8 | D17: 8650.47 | E17: 493.46 | G17: 13 | H17: 2760 | I17: 360 | J17: 18137.31 | K17: 1822.17 | M17: 13 | N17: 0 | O17: 0 | P17: 6660.56 | Q17: 417.71 | S17: 13 | T17: 0 | V17: 260.5 | Y17: 13 | AE17: 13 | AK17: 13 | AQ17: 13 | AW17: 13 | BC17: 13 | BI17: 13 | BO17: 13
A18: 14 | B18: 28885.1 | C18: =936.9+625.5+625.5+534.6+625.5 -> 3348 | D18: 27762.42 | E18: 482.92 | G18: 14 | H18: 28683.69 | I18: =536.4+356.4+477.6+1249.2 -> 2619.6 | J18: 3178.19 | K18: 205.85 | M18: 14 | N18: 28856 | O18: =654+356.4+418.8+1186.8 -> 2616 | P18: 500 | S18: 14 | T18: 24967.4 | U18: =477.6+266.4+297.6+949.8 -> 1991.4 | V18: =33752.5+13047.39 -> 46799.89 | W18: =4402.5+810.59 -> 5213.09 | Y18: 14 | AE18: 14 | AK18: 14 | AQ18: 14 | AW18: 14 | BC18: 14 | BI18: 14 | BO18: 14
A19: WEEKLY TOTALS | B19: =SUM(B12:B18) -> 129237.2 | C19: =SUM(C12:C18) -> 12007.5 | D19: =SUM(D12:D18) -> 75378.96 | E19: =SUM(E12:E18) -> 4015.36 | G19: WEEKLY TOTALS | H19: =SUM(H12:H18) -> 126267.59 | I19: =SUM(I12:I18) -> 12243.6 | J19: =SUM(J12:J18) -> 76791.76 | K19: =SUM(K12:K18) -> 4553.38 | M19: WEEKLY TOTALS | N19: =SUM(N12:N18) -> 127632.2 | O19: =SUM(O12:O18) -> 12288 | P19: =SUM(P12:P18) -> 69868.11 | Q19: =SUM(Q12:Q18) -> 6113.63 | S19: WEEKLY TOTALS | T19: =SUM(T12:T18) -> 134220.9 | U19: =SUM(U12:U18) -> 10728.3 | V19: =SUM(V12:V18) -> 117465.43 | W19: =SUM(W12:W18) -> 10591.48 | Y19: WEEKLY TOTALS | Z19: =SUM(Z12:Z18) -> 3661.6 | AA19: =SUM(AA12:AA18) -> 0 | AB19: =SUM(AB12:AB18) -> 8387.48 | AC19: =SUM(AC12:AC18) -> 431.08 | AE19: WEEKLY TOTALS | AF19: =SUM(AF12:AF18) -> 0 | AG19: =SUM(AG12:AG18) -> 0 | AH19: =SUM(AH12:AH18) -> 0 | AI19: =SUM(AI12:AI18) -> 0 | AK19: WEEKLY TOTALS | AL19: =SUM(AL12:AL18) -> 0 | AM19: =SUM(AM12:AM18) -> 0 | AN19: =SUM(AN12:AN18) -> 0 | AO19: =SUM(AO12:AO18) -> 0 | AQ19: WEEKLY TOTALS | AR19: =SUM(AR12:AR18) -> 0 | AS19: =SUM(AS12:AS18) -> 0 | AT19: =SUM(AT12:AT18) -> 0 | AU19: =SUM(AU12:AU18) -> 0 | AW19: WEEKLY TOTALS | AX19: =SUM(AX12:AX18) -> 0 | AY19: =SUM(AY12:AY18) -> 0 | AZ19: =SUM(AZ12:AZ18) -> 0 | BA19: =SUM(BA12:BA18) -> 0 | BC19: WEEKLY TOTALS | BD19: =SUM(BD12:BD18) -> 0 | BE19: =SUM(BE12:BE18) -> 0 | BF19: =SUM(BF12:BF18) -> 0 | BG19: =SUM(BG12:BG18) -> 0 | BI19: WEEKLY TOTALS | BJ19: =SUM(BJ12:BJ18) -> 0 | BK19: =SUM(BK12:BK18) -> 0 | BL19: =SUM(BL12:BL18) -> 0 | BM19: =SUM(BM12:BM18) -> 0 | BO19: WEEKLY TOTALS | BP19: =SUM(BP12:BP18) -> 0 | BQ19: =SUM(BQ12:BQ18) -> 0 | BR19: =SUM(BR12:BR18) -> 0 | BS19: =SUM(BS12:BS18) -> 0
A20: 15 | B20: 23408.9 | C20: =981+537.3+355.5 -> 1873.8 | D20: =13146.8+850.16 -> 13996.96 | E20: 1714.8 | G20: 15 | H20: 12637.29 | I20: =1429.2 -> 1429.2 | J20: 9539.46 | K20: 501.76 | M20: 15 | N20: 0 | O20: 0 | P20: 27177.58 | Q20: 360.72 | S20: 15 | T20: 28094.5 | U20: =1008.6+626.4+655.8+655.8+670.5 -> 3617.1 | V20: 11092.04 | W20: 658.34 | Y20: 15 | AE20: 15 | AK20: 15 | AQ20: 15 | AW20: 15 | BC20: 15 | BI20: 15 | BO20: 15
A21: 16 | B21: 0 | C21: 0 | D21: =2529.08+6381.41 -> 8910.49 | E21: =329.88+549.81 -> 879.69 | G21: 16 | H21: 0 | I21: 0 | J21: 3016.32 | K21: 23.08 | M21: 16 | N21: 0 | O21: 0 | P21: 1310.98 | S21: 16 | T21: 35129.8 | U21: =597+415.2+477.6+744+744 -> 2977.8 | V21: 19836.08 | W21: 1332.32 | Y21: 16 | AE21: 16 | AK21: 16 | AQ21: 16 | AW21: 16 | BC21: 16 | BI21: 16 | BO21: 16
A22: 17 | B22: 31505.8 | C22: =449.1+355.5+449.1+1160.1 -> 2413.8 | D22: 800 | E22: 0 | G22: 17 | H22: 31482 | I22: =238.8+238.8+178.2+178.2+238.8+238.8+1190.4 -> 2502 | J22: 11740.13 | K22: 620.22 | M22: 17 | N22: 34043.6 | O22: =536.4+356.4+356.4+1190.4 -> 2439.6 | P22: =18571.13+15513.96 -> 34085.09 | Q22: =2422.33+1017.1 -> 3439.43 | S22: 17 | T22: 55558.8 | U22: =1341+1038+1038+4577+1128+477.6+536.4+536.4+536.4 -> 11208.8 | V22: 17204.31 | W22: 1413.57 | Y22: 17 | AE22: 17 | AK22: 17 | AQ22: 17 | AW22: 17 | BC22: 17 | BI22: 17 | BO22: 17
A23: 18 | B23: 0 | C23: 0 | D23: 8858.38 | E23: 710.66 | G23: 18 | H23: 0 | I23: 0 | J23: 205.96 | M23: 18 | N23: 29122.6 | O23: =891+714.6+714.6+714.6+744 -> 3778.8 | P23: 9766.31 | Q23: 620.59 | S23: 18 | T23: 25209.6 | U23: =955.2+534.6+655.8 -> 2145.6 | V23: 8664.51 | W23: 550.46 | Y23: 18 | AE23: 18 | AK23: 18 | AQ23: 18 | AW23: 18 | BC23: 18 | BI23: 18 | BO23: 18
A24: 19 | B24: =7859.1+4238.9 -> 12098 | C24: =1025.1+552.9 -> 1578 | D24: 0 | E24: 0 | G24: 19 | H24: 26222 | I24: =418.8+356.4+297.6+1069.2 -> 2142 | J24: 35049.91 | K24: 4093.5 | M24: 19 | N24: 21171.2 | O24: =477.6+356.4+297.6+563.5 -> 1695.1 | P24: 800 | S24: 19 | Y24: 19 | AE24: 19 | AK24: 19 | AQ24: 19 | AW24: 19 | BC24: 19 | BI24: 19 | BO24: 19
A25: 20 | B25: 25595.6 | C25: =449.1+355.5+449.1+936.9 -> 2190.6 | D25: 14014.66 | E25: 405.27 | G25: 20 | H25: 32333.4 | I25: =538.2+949.8+655.8+655.8+655.8+744 -> 4199.4 | J25: 8944.16 | K25: 845.75 | M25: 20 | N25: 3668.5 | O25: =209.4+269.1 -> 478.5 | P25: 12864.27 | Q25: 1246.31 | S25: 20 | Y25: 20 | AE25: 20 | AK25: 20 | AQ25: 20 | AW25: 20 | BC25: 20 | BI25: 20 | BO25: 20
A26: 21 | B26: 30026.7 | C26: =1116+684.3+684.3+534.6+684.3 -> 3703.5 | D26: =24276.5+5275.21 -> 29551.71 | E26: =3166.5+372.47 -> 3538.97 | G26: 21 | H26: 26628 | I26: =481.2+356.4+360+1131.6 -> 2329.2 | J26: 7884.99 | K26: 24.13 | M26: 21 | N26: 34646 | O26: =775.2+415.2+477.6+1488 -> 3156 | P26: 800 | S26: 21 | T26: 26612.8 | U26: =657.6+356.4+477.6+1249.2 -> 2740.8 | V26: 7384.62 | W26: 351.57 | Y26: 21 | AE26: 21 | AK26: 21 | AQ26: 21 | AW26: 21 | BC26: 21 | BI26: 21 | BO26: 21
A27: WEEKLY TOTALS | B27: =SUM(B20:B26) -> 122635 | C27: =SUM(C20:C26) -> 11759.7 | D27: =SUM(D20:D26) -> 76132.2 | E27: =SUM(E20:E26) -> 7249.39 | G27: WEEKLY TOTALS | H27: =SUM(H20:H26) -> 129302.69 | I27: =SUM(I20:I26) -> 12601.8 | J27: =SUM(J20:J26) -> 76380.93 | K27: =SUM(K20:K26) -> 6108.44 | M27: WEEKLY TOTALS | N27: =SUM(N20:N26) -> 122651.9 | O27: =SUM(O20:O26) -> 11548 | P27: =SUM(P20:P26) -> 86804.23 | Q27: =SUM(Q20:Q26) -> 5667.05 | S27: WEEKLY TOTALS | T27: =SUM(T20:T26) -> 170605.5 | U27: =SUM(U20:U26) -> 22690.1 | V27: =SUM(V20:V26) -> 64181.56 | W27: =SUM(W20:W26) -> 4306.26 | Y27: WEEKLY TOTALS | Z27: =SUM(Z20:Z26) -> 0 | AA27: =SUM(AA20:AA26) -> 0 | AB27: =SUM(AB20:AB26) -> 0 | AC27: =SUM(AC20:AC26) -> 0 | AE27: WEEKLY TOTALS | AF27: =SUM(AF20:AF26) -> 0 | AG27: =SUM(AG20:AG26) -> 0 | AH27: =SUM(AH20:AH26) -> 0 | AI27: =SUM(AI20:AI26) -> 0 | AK27: WEEKLY TOTALS | AL27: =SUM(AL20:AL26) -> 0 | AM27: =SUM(AM20:AM26) -> 0 | AN27: =SUM(AN20:AN26) -> 0 | AO27: =SUM(AO20:AO26) -> 0 | AQ27: WEEKLY TOTALS | AR27: =SUM(AR20:AR26) -> 0 | AS27: =SUM(AS20:AS26) -> 0 | AT27: =SUM(AT20:AT26) -> 0 | AU27: =SUM(AU20:AU26) -> 0 | AW27: WEEKLY TOTALS | AX27: =SUM(AX20:AX26) -> 0 | AY27: =SUM(AY20:AY26) -> 0 | AZ27: =SUM(AZ20:AZ26) -> 0 | BA27: =SUM(BA20:BA26) -> 0 | BC27: WEEKLY TOTALS | BD27: =SUM(BD20:BD26) -> 0 | BE27: =SUM(BE20:BE26) -> 0 | BF27: =SUM(BF20:BF26) -> 0 | BG27: =SUM(BG20:BG26) -> 0 | BI27: WEEKLY TOTALS | BJ27: =SUM(BJ20:BJ26) -> 0 | BK27: =SUM(BK20:BK26) -> 0 | BL27: =SUM(BL20:BL26) -> 0 | BM27: =SUM(BM20:BM26) -> 0 | BO27: WEEKLY TOTALS | BP27: =SUM(BP20:BP26) -> 0 | BQ27: =SUM(BQ20:BQ26) -> 0 | BR27: =SUM(BR20:BR26) -> 0 | BS27: =SUM(BS20:BS26) -> 0
